Workbook

Sheet Opzet
A1: Index | B1: =COLUMN() -> 2 | C1: =COLUMN() -> 3 | D1: =COLUMN() -> 4 | E1: =COLUMN() -> 5 | F1: =COLUMN() -> 6 | G1: =COLUMN() -> 7 | H1: =COLUMN() -> 8 | I1: =COLUMN() -> 9 | ... P1: =COLUMN() -> 16
A2: =ROW() -> 2 | B2: Omschrijving | C2: Opening | D2: Jaar 1 | E2: =D2 -> Jaar 1 | F2: =E2 -> Jaar 1 | G2: =F2 -> Jaar 1 | H2: =G2 -> Jaar 1 | I2: =H2 -> Jaar 1 | J2: =I2 -> Jaar 1 | K2: =J2 -> Jaar 1 | L2: =K2 -> Jaar 1 | ... P2: =O2 -> Jaar 1
A3: =ROW() -> 3 | D3: ACT/BUD/FCST | E3: ACT/BUD/FCST | F3: ACT/BUD/FCST | G3: ACT/BUD/FCST | H3: ACT/BUD/FCST | I3: ACT/BUD/FCST | J3: ACT/BUD/FCST | K3: ACT/BUD/FCST | L3: ACT/BUD/FCST | M3: ACT/BUD/FCST | N3: ACT/BUD/FCST | O3: ACT/BUD/FCST | P3: ACT/BUD/FCST
A4: =ROW() -> 4 | D4: Maand 1 | E4: Maand 2 | F4: Maand 3 | G4: Maand 4 | H4: Maand 5 | I4: Maand 6 | J4: Maand 7 | K4: Maand 8 | L4: Maand 9 | M4: Maand 10 | N4: Maand 11 | O4: Maand 12 | P4: Totaal
A5: =ROW() -> 5
A6: =ROW() -> 6
A7: =ROW() -> 7
A8: =ROW() -> 8
A9: =ROW() -> 9
A10: =ROW() -> 10
A11: =ROW() -> 11
A12: =ROW() -> 12
A13: =ROW() -> 13
A14: =ROW() -> 14
A15: =ROW() -> 15
A16: =ROW() -> 16
... A27: =ROW() -> 27

Sheet RFF
A1: Index | B1: =COLUMN() -> 2 | C1: =COLUMN() -> 3 | D1: =COLUMN() -> 4 | E1: =COLUMN() -> 5 | F1: =COLUMN() -> 6 | G1: =COLUMN() -> 7 | H1: =COLUMN() -> 8 | I1: =COLUMN() -> 9 | ... AP1: =COLUMN() -> 42
A2: =ROW() -> 2 | B2: Omschrijving | C2: Opening | D2: 2026 | E2: =D2 -> 2026 | F2: =E2 -> 2026 | G2: =F2 -> 2026 | H2: =G2 -> 2026 | I2: =H2 -> 2026 | J2: =I2 -> 2026 | K2: =J2 -> 2026 | L2: =K2 -> 2026 | ... P2: =O2 -> 2026 | Q2: 2027 | R2: =Q2 -> 2027 | S2: =R2 -> 2027 | T2: =S2 -> 2027 | U2: =T2 -> 2027 | V2: =U2 -> 2027 | W2: =V2 -> 2027 | X2: =W2 -> 2027 | Y2: =X2 -> 2027 | ... AC2: =AB2 -> 2027 | AD2: 2028 | AE2: =AD2 -> 2028 | AF2: =AE2 -> 2028 | AG2: =AF2 -> 2028 | AH2: =AG2 -> 2028 | AI2: =AH2 -> 2028 | AJ2: =AI2 -> 2028 | AK2: =AJ2 -> 2028 | AL2: =AK2 -> 2028 | ... AP2: =AO2 -> 2028
A3: =ROW() -> 3 | D3: FCST | E3: =D3 -> FCST | F3: =E3 -> FCST | G3: =F3 -> FCST | H3: =G3 -> FCST | I3: =H3 -> FCST | J3: =I3 -> FCST | K3: =J3 -> FCST | L3: =K3 -> FCST | ... P3: =O3 -> FCST | Q3: FCST | R3: =Q3 -> FCST | S3: =R3 -> FCST | T3: =S3 -> FCST | U3: =T3 -> FCST | V3: =U3 -> FCST | W3: =V3 -> FCST | X3: =W3 -> FCST | Y3: =X3 -> FCST | ... AC3: =AB3 -> FCST | AD3: FCST | AE3: =AD3 -> FCST | AF3: =AE3 -> FCST | AG3: =AF3 -> FCST | AH3: =AG3 -> FCST | AI3: =AH3 -> FCST | AJ3: =AI3 -> FCST | AK3: =AJ3 -> FCST | AL3: =AK3 -> FCST | ... AP3: =AO3 -> FCST
A4: =ROW() -> 4 | D4: 1 | E4: =D4+1 -> 2 | F4: =E4+1 -> 3 | G4: =F4+1 -> 4 | H4: =G4+1 -> 5 | I4: =H4+1 -> 6 | J4: =I4+1 -> 7 | K4: =J4+1 -> 8 | L4: =K4+1 -> 9 | ... O4: =N4+1 -> 12 | P4: Totaal | Q4: 1 | R4: =Q4+1 -> 2 | S4: =R4+1 -> 3 | T4: =S4+1 -> 4 | U4: =T4+1 -> 5 | V4: =U4+1 -> 6 | W4: =V4+1 -> 7 | X4: =W4+1 -> 8 | Y4: =X4+1 -> 9 | ... AB4: =AA4+1 -> 12 | AC4: Totaal | AD4: 1 | AE4: =AD4+1 -> 2 | AF4: =AE4+1 -> 3 | AG4: =AF4+1 -> 4 | AH4: =AG4+1 -> 5 | AI4: =AH4+1 -> 6 | AJ4: =AI4+1 -> 7 | AK4: =AJ4+1 -> 8 | AL4: =AK4+1 -> 9 | ... AO4: =AN4+1 -> 12 | AP4: Totaal
A5: =ROW() -> 5
A6: =ROW() -> 6 | B6: KPI
A7: =ROW() -> 7 | B7: Aantal klanten Foundation | D7: 0 | E7: 0 | F7: 0 | G7: 1 | H7: 1 | I7: 1 | J7: 2 | K7: 2 | L7: 2 | M7: 3 | N7: 3 | O7: 3 | P7: =AVERAGE(D7:O7) -> 1.5 | Q7: =O7+2 -> 5 | R7: =Q7 -> 5 | S7: =R7+1 -> 6 | T7: =S7 -> 6 | U7: =T7+1 -> 7 | V7: =U7 -> 7 | W7: =V7 -> 7 | X7: =W7 -> 7 | Y7: =X7+1 -> 8 | Z7: =Y7 -> 8 | AA7: =Z7 -> 8 | AB7: =AA7 -> 8 | AC7: =AVERAGE(Q7:AB7) -> 6.8333333 | AD7: =AB7+2 -> 10 | AE7: =AD7 -> 10 | AF7: =AE7+1 -> 11 | AG7: =AF7 -> 11 | AH7: =AG7+1 -> 12 | AI7: =AH7 -> 12 | AJ7: =AI7 -> 12 | AK7: =AJ7 -> 12 | AL7: =AK7+1 -> 13 | AM7: =AL7 -> 13 | AN7: =AM7 -> 13 | AO7: =AN7 -> 13 | AP7: =AVERAGE(AD7:AO7) -> 11.833333
A8: =ROW() -> 8 | B8: Aantal klanten Growth | D8: 0 | E8: 0 | F8: 0 | G8: 0 | H8: 0 | I8: 0 | J8: 1 | K8: 1 | L8: 1 | M8: 1 | N8: 1 | O8: 1 | P8: =AVERAGE(D8:O8) -> 0.5 | Q8: =O8*1 -> 1 | R8: =Q8 -> 1 | S8: =R8 -> 1 | T8: =S8+1 -> 2 | U8: =T8 -> 2 | V8: =U8 -> 2 | W8: =V8 -> 2 | X8: =W8 -> 2 | Y8: =X8 -> 2 | Z8: =Y8 -> 2 | AA8: =Z8 -> 2 | AB8: =AA8 -> 2 | AC8: =AVERAGE(Q8:AB8) -> 1.75 | AD8: =AB8+1 -> 3 | AE8: =AD8 -> 3 | AF8: =AE8 -> 3 | AG8: =AF8+1 -> 4 | AH8: =AG8 -> 4 | AI8: =AH8 -> 4 | AJ8: =AI8 -> 4 | AK8: =AJ8 -> 4 | AL8: =AK8 -> 4 | AM8: =AL8 -> 4 | AN8: =AM8 -> 4 | AO8: =AN8 -> 4 | AP8: =AVERAGE(AD8:AO8) -> 3.75
A9: =ROW() -> 9 | B9: Aantal klanten Scale | D9: 0 | E9: 0 | F9: 0 | G9: 0 | H9: 0 | I9: 0 | J9: 0 | K9: 0 | L9: 0 | M9: 0.5 | N9: 0.5 | O9: 0.5 | P9: =AVERAGE(D9:O9) -> 0.125 | Q9: =O9*2 -> 1 | R9: =Q9 -> 1 | S9: =R9 -> 1 | T9: =S9 -> 1 | U9: =T9 -> 1 | V9: =U9+0.5 -> 1.5 | W9: =V9 -> 1.5 | X9: =W9 -> 1.5 | Y9: =X9 -> 1.5 | Z9: =Y9+0.5 -> 2 | AA9: =Z9 -> 2 | AB9: =AA9 -> 2 | AC9: =AVERAGE(Q9:AB9) -> 1.4166667 | AD9: =AB9+1 -> 3 | AE9: =AD9 -> 3 | AF9: =AE9 -> 3 | AG9: =AF9 -> 3 | AH9: =AG9 -> 3 | AI9: =AH9+0.5 -> 3.5 | AJ9: =AI9 -> 3.5 | AK9: =AJ9 -> 3.5 | AL9: =AK9 -> 3.5 | AM9: =AL9+0.5 -> 4 | AN9: =AM9 -> 4 | AO9: =AN9 -> 4 | AP9: =AVERAGE(AD9:AO9) -> 3.4166667
A10: =ROW() -> 10
A11: =ROW() -> 11 | B11: Tarief klanten Foundation | D11: =Pakketten!C3 -> 6750 | E11: =D11 -> 6750 | F11: =E11 -> 6750 | G11: =F11 -> 6750 | H11: =G11 -> 6750 | I11: =H11 -> 6750 | J11: =I11 -> 6750 | K11: =J11 -> 6750 | L11: =K11 -> 6750 | ... O11: =N11 -> 6750 | P11: =AVERAGE(D11:O11) -> 6750 | Q11: =O11*1.05 -> 7087.5 | R11: =Q11 -> 7087.5 | S11: =R11 -> 7087.5 | T11: =S11 -> 7087.5 | U11: =T11 -> 7087.5 | V11: =U11 -> 7087.5 | W11: =V11 -> 7087.5 | X11: =W11 -> 7087.5 | Y11: =X11 -> 7087.5 | ... AB11: =AA11 -> 7087.5 | AC11: =AVERAGE(Q11:AB11) -> 7087.5 | AD11: =AB11*1.05 -> 7441.875 | AE11: =AD11 -> 7441.875 | AF11: =AE11 -> 7441.875 | AG11: =AF11 -> 7441.875 | AH11: =AG11 -> 7441.875 | AI11: =AH11 -> 7441.875 | AJ11: =AI11 -> 7441.875 | AK11: =AJ11 -> 7441.875 | AL11: =AK11 -> 7441.875 | ... AO11: =AN11 -> 7441.875 | AP11: =AVERAGE(AD11:AO11) -> 7441.875
A12: =ROW() -> 12 | B12: Tarief klanten Growth | D12: =Pakketten!K3 -> 17000 | E12: =D12 -> 17000 | F12: =E12 -> 17000 | G12: =F12 -> 17000 | H12: =G12 -> 17000 | I12: =H12 -> 17000 | J12: =I12 -> 17000 | K12: =J12 -> 17000 | L12: =K12 -> 17000 | ... O12: =N12 -> 17000 | P12: =AVERAGE(D12:O12) -> 17000 | Q12: =O12*1.05 -> 17850 | R12: =Q12 -> 17850 | S12: =R12 -> 17850 | T12: =S12 -> 17850 | U12: =T12 -> 17850 | V12: =U12 -> 17850 | W12: =V12 -> 17850 | X12: =W12 -> 17850 | Y12: =X12 -> 17850 | ... AB12: =AA12 -> 17850 | AC12: =AVERAGE(Q12:AB12) -> 17850 | AD12: =AB12*1.05 -> 18742.5 | AE12: =AD12 -> 18742.5 | AF12: =AE12 -> 18742.5 | AG12: =AF12 -> 18742.5 | AH12: =AG12 -> 18742.5 | AI12: =AH12 -> 18742.5 | AJ12: =AI12 -> 18742.5 | AK12: =AJ12 -> 18742.5 | AL12: =AK12 -> 18742.5 | ... AO12: =AN12 -> 18742.5 | AP12: =AVERAGE(AD12:AO12) -> 18742.5
A13: =ROW() -> 13 | B13: Tarief klanten Scale | D13: =Pakketten!S3 -> 27000 | E13: =D13 -> 27000 | F13: =E13 -> 27000 | G13: =F13 -> 27000 | H13: =G13 -> 27000 | I13: =H13 -> 27000 | J13: =I13 -> 27000 | K13: =J13 -> 27000 | L13: =K13 -> 27000 | ... O13: =N13 -> 27000 | P13: =AVERAGE(D13:O13) -> 27000 | Q13: =O13*1.05 -> 28350 | R13: =Q13 -> 28350 | S13: =R13 -> 28350 | T13: =S13 -> 28350 | U13: =T13 -> 28350 | V13: =U13 -> 28350 | W13: =V13 -> 28350 | X13: =W13 -> 28350 | Y13: =X13 -> 28350 | ... AB13: =AA13 -> 28350 | AC13: =AVERAGE(Q13:AB13) -> 28350 | AD13: =AB13*1.05 -> 29767.5 | AE13: =AD13 -> 29767.5 | AF13: =AE13 -> 29767.5 | AG13: =AF13 -> 29767.5 | AH13: =AG13 -> 29767.5 | AI13: =AH13 -> 29767.5 | AJ13: =AI13 -> 29767.5 | AK13: =AJ13 -> 29767.5 | AL13: =AK13 -> 29767.5 | ... AO13: =AN13 -> 29767.5 | AP13: =AVERAGE(AD13:AO13) -> 29767.5
A14: =ROW() -> 14
A15: =ROW() -> 15 | B15: MRR klanten Foundation | D15: =D7*D11 -> 0 | E15: =E7*E11 -> 0 | F15: =F7*F11 -> 0 | G15: =G7*G11 -> 6750 | H15: =H7*H11 -> 6750 | I15: =I7*I11 -> 6750 | J15: =J7*J11 -> 13500 | K15: =K7*K11 -> 13500 | ... O15: =O7*O11 -> 20250 | P15: =AVERAGE(D15:O15) -> 10125 | Q15: =Q7*Q11 -> 35437.5 | R15: =R7*R11 -> 35437.5 | S15: =S7*S11 -> 42525 | T15: =T7*T11 -> 42525 | U15: =U7*U11 -> 49612.5 | V15: =V7*V11 -> 49612.5 | W15: =W7*W11 -> 49612.5 | X15: =X7*X11 -> 49612.5 | ... AB15: =AB7*AB11 -> 56700 | AC15: =AVERAGE(Q15:AB15) -> 48431.25 | AD15: =AD7*AD11 -> 74418.75 | AE15: =AE7*AE11 -> 74418.75 | AF15: =AF7*AF11 -> 81860.625 | AG15: =AG7*AG11 -> 81860.625 | AH15: =AH7*AH11 -> 89302.5 | AI15: =AI7*AI11 -> 89302.5 | AJ15: =AJ7*AJ11 -> 89302.5 | AK15: =AK7*AK11 -> 89302.5 | ... AO15: =AO7*AO11 -> 96744.375 | AP15: =AVERAGE(AD15:AO15) -> 88062.188
A16: =ROW() -> 16 | B16: MRR klanten Growth | D16: =D8*D12 -> 0 | E16: =E8*E12 -> 0 | F16: =F8*F12 -> 0 | G16: =G8*G12 -> 0 | H16: =H8*H12 -> 0 | I16: =I8*I12 -> 0 | J16: =J8*J12 -> 17000 | K16: =K8*K12 -> 17000 | ... O16: =O8*O12 -> 17000 | P16: =AVERAGE(D16:O16) -> 8500 | Q16: =Q8*Q12 -> 17850 | R16: =R8*R12 -> 17850 | S16: =S8*S12 -> 17850 | T16: =T8*T12 -> 35700 | U16: =U8*U12 -> 35700 | V16: =V8*V12 -> 35700 | W16: =W8*W12 -> 35700 | X16: =X8*X12 -> 35700 | ... AB16: =AB8*AB12 -> 35700 | AC16: =AVERAGE(Q16:AB16) -> 31237.5 | AD16: =AD8*AD12 -> 56227.5 | AE16: =AE8*AE12 -> 56227.5 | AF16: =AF8*AF12 -> 56227.5 | AG16: =AG8*AG12 -> 74970 | AH16: =AH8*AH12 -> 74970 | AI16: =AI8*AI12 -> 74970 | AJ16: =AJ8*AJ12 -> 74970 | AK16: =AK8*AK12 -> 74970 | ... AO16: =AO8*AO12 -> 74970 | AP16: =AVERAGE(AD16:AO16) -> 70284.375
A17: =ROW() -> 17 | B17: MRR klanten Scale | D17: =D9*D13 -> 0 | E17: =E9*E13 -> 0 | F17: =F9*F13 -> 0 | G17: =G9*G13 -> 0 | H17: =H9*H13 -> 0 | I17: =I9*I13 -> 0 | J17: =J9*J13 -> 0 | K17: =K9*K13 -> 0 | ... O17: =O9*O13 -> 13500 | P17: =AVERAGE(D17:O17) -> 3375 | Q17: =Q9*Q13 -> 28350 | R17: =R9*R13 -> 28350 | S17: =S9*S13 -> 28350 | T17: =T9*T13 -> 28350 | U17: =U9*U13 -> 28350 | V17: =V9*V13 -> 42525 | W17: =W9*W13 -> 42525 | X17: =X9*X13 -> 42525 | ... AB17: =AB9*AB13 -> 56700 | AC17: =AVERAGE(Q17:AB17) -> 40162.5 | AD17: =AD9*AD13 -> 89302.5 | AE17: =AE9*AE13 -> 89302.5 | AF17: =AF9*AF13 -> 89302.5 | AG17: =AG9*AG13 -> 89302.5 | AH17: =AH9*AH13 -> 89302.5 | AI17: =AI9*AI13 -> 104186.25 | AJ17: =AJ9*AJ13 -> 104186.25 | AK17: =AK9*AK13 -> 104186.25 | ... AO17: =AO9*AO13 -> 119070 | AP17: =AVERAGE(AD17:AO17) -> 101705.62
A18: =ROW() -> 18
A19: =ROW() -> 19 | B19: FTEs
A20: =ROW() -> 20 | B20: - CEO (C-level) | D20: =OPEX!D17 -> 0.2 | E20: =OPEX!E17 -> 0.2 | F20: =OPEX!F17 -> 0.2 | G20: =OPEX!G17 -> 0.2 | H20: =OPEX!H17 -> 0.2 | I20: =OPEX!I17 -> 0.2 | J20: =OPEX!J17 -> 0.2 | K20: =OPEX!K17 -> 0.2 | L20: =OPEX!L17 -> 0.2 | M20: 0.6 | N20: 0.6 | O20: 0.6 | P20: =AVERAGE(D20:O20) -> 0.3 | Q20: 0.5 | R20: =Q20 -> 0.5 | S20: =R20 -> 0.5 | T20: 0.6 | U20: =T20 -> 0.6 | V20: =U20 -> 0.6 | W20: =V20 -> 0.6 | X20: =W20 -> 0.6 | Y20: 0.8 | Z20: =Y20 -> 0.8 | AA20: =Z20 -> 0.8 | AB20: =AA20 -> 0.8 | AC20: =AVERAGE(Q20:AB20) -> 0.64166667 | AD20: 1.4 | AE20: =AD20 -> 1.4 | AF20: =AE20 -> 1.4 | AG20: =AF20 -> 1.4 | AH20: =AG20 -> 1.4 | AI20: =AH20 -> 1.4 | AJ20: =AI20 -> 1.4 | AK20: =AJ20 -> 1.4 | AL20: =AK20 -> 1.4 | AM20: 1.6 | AN20: =AM20 -> 1.6 | AO20: =AN20 -> 1.6 | AP20: =AVERAGE(AD20:AO20) -> 1.45
A21: =ROW() -> 21 | B21: - CFO (C-level) | D21: =OPEX!D18 -> 0.6 | E21: =OPEX!E18 -> 0.6 | F21: =OPEX!F18 -> 0.6 | G21: =OPEX!G18 -> 0.6 | H21: =OPEX!H18 -> 0.6 | I21: =OPEX!I18 -> 0.6 | J21: =OPEX!J18 -> 0.6 | K21: =OPEX!K18 -> 0.6 | ... O21: =OPEX!O18 -> 0.6 | P21: =AVERAGE(D21:O21) -> 0.6 | Q21: 0.8 | R21: =Q21 -> 0.8 | S21: =R21 -> 0.8 | T21: 1 | U21: 1.4 | V21: =U21 -> 1.4 | W21: =V21 -> 1.4 | X21: =W21 -> 1.4 | Y21: =X21 -> 1.4 | Z21: =Y21 -> 1.4 | AA21: =Z21 -> 1.4 | AB21: =AA21 -> 1.4 | AC21: =AVERAGE(Q21:AB21) -> 1.2166667 | AD21: 2 | AE21: =AD21 -> 2 | AF21: =AE21 -> 2 | AG21: 2.2 | AH21: =AG21 -> 2.2 | AI21: =AH21 -> 2.2 | AJ21: =AI21 -> 2.2 | AK21: =AJ21 -> 2.2 | AL21: =AK21 -> 2.2 | AM21: 2.6 | AN21: =AM21 -> 2.6 | AO21: =AN21 -> 2.6 | AP21: =AVERAGE(AD21:AO21) -> 2.25
A22: =ROW() -> 22 | B22: - CMO (Senior-level) | D22: =OPEX!D19 -> 0 | E22: =OPEX!E19 -> 0 | F22: =OPEX!F19 -> 0 | G22: =OPEX!G19 -> 0 | H22: =OPEX!H19 -> 0 | I22: =OPEX!I19 -> 0 | J22: =OPEX!J19 -> 0.4 | K22: =OPEX!K19 -> 0.4 | L22: =OPEX!L19 -> 0.4 | M22: 0.6 | N22: 0.6 | O22: 0.6 | P22: =AVERAGE(D22:O22) -> 0.25 | Q22: 0.8 | R22: =Q22 -> 0.8 | S22: =R22 -> 0.8 | T22: 1 | U22: 1.2 | V22: =U22 -> 1.2 | W22: =V22 -> 1.2 | X22: =W22 -> 1.2 | Y22: =X22 -> 1.2 | Z22: 1.4 | AA22: =Z22 -> 1.4 | AB22: =AA22 -> 1.4 | AC22: =AVERAGE(Q22:AB22) -> 1.1333333 | AD22: 2 | AE22: =AD22 -> 2 | AF22: =AE22 -> 2 | AG22: 2.2 | AH22: =AG22 -> 2.2 | AI22: =AH22 -> 2.2 | AJ22: =AI22 -> 2.2 | AK22: =AJ22 -> 2.2 | AL22: =AK22 -> 2.2 | AM22: 2.6 | AN22: =AM22 -> 2.6 | AO22: =AN22 -> 2.6 | AP22: =AVERAGE(AD22:AO22) -> 2.25
A23: =ROW() -> 23 | B23: - CTO (Senior-level) | D23: =OPEX!D20 -> 0 | E23: =OPEX!E20 -> 0 | F23: =OPEX!F20 -> 0 | G23: =OPEX!G20 -> 0 | H23: =OPEX!H20 -> 0 | I23: =OPEX!I20 -> 0 | J23: =OPEX!J20 -> 0.4 | K23: =OPEX!K20 -> 0.4 | L23: =OPEX!L20 -> 0.4 | M23: 0.6 | N23: 0.6 | O23: 0.6 | P23: =AVERAGE(D23:O23) -> 0.25 | Q23: 0.8 | R23: =Q23 -> 0.8 | S23: =R23 -> 0.8 | T23: 1 | U23: 1.2 | V23: =U23 -> 1.2 | W23: =V23 -> 1.2 | X23: =W23 -> 1.2 | Y23: =X23 -> 1.2 | Z23: 1.4 | AA23: =Z23 -> 1.4 | AB23: =AA23 -> 1.4 | AC23: =AVERAGE(Q23:AB23) -> 1.1333333 | AD23: 2 | AE23: =AD23 -> 2 | AF23: =AE23 -> 2 | AG23: 2.4 | AH23: =AG23 -> 2.4 | AI23: =AH23 -> 2.4 | AJ23: =AI23 -> 2.4 | AK23: =AJ23 -> 2.4 | AL23: =AK23 -> 2.4 | AM23: 2.6 | AN23: =AM23 -> 2.6 | AO23: =AN23 -> 2.6 | AP23: =AVERAGE(AD23:AO23) -> 2.35
A24: =ROW() -> 24 | B24: - HR partner (Senior-level) | D24: =OPEX!D21 -> 0 | E24: =OPEX!E21 -> 0 | F24: =OPEX!F21 -> 0 | G24: =OPEX!G21 -> 0 | H24: =OPEX!H21 -> 0 | I24: =OPEX!I21 -> 0 | J24: =OPEX!J21 -> 0.4 | K24: =OPEX!K21 -> 0.4 | L24: =OPEX!L21 -> 0.4 | M24: 0.6 | N24: 0.6 | O24: 0.6 | P24: =AVERAGE(D24:O24) -> 0.25 | Q24: 0.8 | R24: 0.8 | S24: =R24 -> 0.8 | T24: 1.4 | U24: =T24 -> 1.4 | V24: =U24 -> 1.4 | W24: =V24 -> 1.4 | X24: =W24 -> 1.4 | Y24: =X24 -> 1.4 | Z24: =Y24 -> 1.4 | AA24: =Z24 -> 1.4 | AB24: =AA24 -> 1.4 | AC24: =AVERAGE(Q24:AB24) -> 1.25 | AD24: 2 | AE24: =AD24 -> 2 | AF24: =AE24 -> 2 | AG24: 2.4 | AH24: =AG24 -> 2.4 | AI24: =AH24 -> 2.4 | AJ24: =AI24 -> 2.4 | AK24: =AJ24 -> 2.4 | AL24: =AK24 -> 2.4 | AM24: 2.6 | AN24: =AM24 -> 2.6 | AO24: =AN24 -> 2.6 | AP24: =AVERAGE(AD24:AO24) -> 2.35
A25: =ROW() -> 25 | B25: - Finance admin (Sedior-level) | D25: =OPEX!D22 -> 0.4 | E25: =OPEX!E22 -> 0.4 | F25: =OPEX!F22 -> 0.4 | G25: =OPEX!G22 -> 0.4 | H25: =OPEX!H22 -> 0.4 | I25: =OPEX!I22 -> 0.4 | J25: 0.4 | K25: 0.4 | L25: 0.4 | M25: 0.6 | N25: =M25 -> 0.6 | O25: =N25 -> 0.6 | P25: =AVERAGE(D25:O25) -> 0.45 | Q25: 1 | R25: =Q25 -> 1 | S25: =R25 -> 1 | T25: 1.4 | U25: =T25 -> 1.4 | V25: =U25 -> 1.4 | W25: =V25 -> 1.4 | X25: =W25 -> 1.4 | Y25: =X25 -> 1.4 | Z25: =Y25 -> 1.4 | AA25: =Z25 -> 1.4 | AB25: =AA25 -> 1.4 | AC25: =AVERAGE(Q25:AB25) -> 1.3 | AD25: 2 | AE25: =AD25 -> 2 | AF25: =AE25 -> 2 | AG25: 2.4 | AH25: =AG25 -> 2.4 | AI25: =AH25 -> 2.4 | AJ25: =AI25 -> 2.4 | AK25: =AJ25 -> 2.4 | AL25: =AK25 -> 2.4 | AM25: 2.6 | AN25: =AM25 -> 2.6 | AO25: =AN25 -> 2.6 | AP25: =AVERAGE(AD25:AO25) -> 2.35
A26: =ROW() -> 26 | B26: - HR admin (Medior-level) | D26: =OPEX!D23 -> 0 | E26: =OPEX!E23 -> 0 | F26: =OPEX!F23 -> 0 | G26: =OPEX!G23 -> 0 | H26: =OPEX!H23 -> 0 | I26: =OPEX!I23 -> 0 | J26: =OPEX!J23 -> 0 | K26: =OPEX!K23 -> 0 | ... O26: =OPEX!O23 -> 0 | P26: =AVERAGE(D26:O26) -> 0 | Q26: =O26 -> 0 | R26: =Q26 -> 0 | S26: =R26 -> 0 | T26: =S26 -> 0 | U26: =T26 -> 0 | V26: =U26 -> 0 | W26: =V26 -> 0 | X26: =W26 -> 0 | Y26: =X26 -> 0 | ... AB26: =AA26 -> 0 | AC26: =AVERAGE(Q26:AB26) -> 0 | AD26: =AB26 -> 0 | AE26: =AD26 -> 0 | AF26: =AE26 -> 0 | AG26: =AF26 -> 0 | AH26: =AG26 -> 0 | AI26: =AH26 -> 0 | AJ26: =AI26 -> 0 | AK26: =AJ26 -> 0 | AL26: =AK26 -> 0 | ... AO26: =AN26 -> 0 | AP26: =AVERAGE(AD26:AO26) -> 0
A27: =ROW() -> 27 | B27: - Backoffice support (Junior-level) | D27: =OPEX!D24 -> 0 | E27: =OPEX!E24 -> 0 | F27: =OPEX!F24 -> 0 | G27: =OPEX!G24 -> 0 | H27: =OPEX!H24 -> 0 | I27: =OPEX!I24 -> 0 | J27: =OPEX!J24 -> 0.4 | K27: =OPEX!K24 -> 0.4 | ... O27: =OPEX!O24 -> 1 | P27: =AVERAGE(D27:O27) -> 0.4 | Q27: 1.6 | R27: =Q27 -> 1.6 | S27: =R27 -> 1.6 | T27: 2 | U27: 2.4 | V27: =U27 -> 2.4 | W27: =V27 -> 2.4 | X27: =W27 -> 2.4 | Y27: =X27 -> 2.4 | Z27: 3 | AA27: =Z27 -> 3 | AB27: =AA27 -> 3 | AC27: =AVERAGE(Q27:AB27) -> 2.3166667 | AD27: 4 | AE27: =AD27 -> 4 | AF27: =AE27 -> 4 | AG27: 4.4 | AH27: =AG27 -> 4.4 | AI27: =AH27 -> 4.4 | AJ27: =AI27 -> 4.4 | AK27: =AJ27 -> 4.4 | AL27: =AK27 -> 4.4 | AM27: 4.6 | AN27: =AM27 -> 4.6 | AO27: =AN27 -> 4.6 | AP27: =AVERAGE(AD27:AO27) -> 4.35
A28: =ROW() -> 28 | B28: - Data engineer (Medior-level) | D28: =OPEX!D25 -> 0 | E28: =OPEX!E25 -> 0 | F28: =OPEX!F25 -> 0 | G28: =OPEX!G25 -> 0 | H28: =OPEX!H25 -> 0 | I28: =OPEX!I25 -> 0 | J28: =OPEX!J25 -> 0.4 | K28: =OPEX!K25 -> 0.4 | ... O28: =OPEX!O25 -> 0.4 | P28: =AVERAGE(D28:O28) -> 0.2 | Q28: =O28 -> 0.4 | R28: =Q28 -> 0.4 | S28: =R28 -> 0.4 | T28: =S28 -> 0.4 | U28: =T28 -> 0.4 | V28: =U28 -> 0.4 | W28: =V28 -> 0.4 | X28: =W28 -> 0.4 | Y28: =X28 -> 0.4 | ... AB28: =AA28 -> 0.4 | AC28: =AVERAGE(Q28:AB28) -> 0.4 | AD28: =AB28 -> 0.4 | AE28: =AD28 -> 0.4 | AF28: =AE28 -> 0.4 | AG28: =AF28 -> 0.4 | AH28: =AG28 -> 0.4 | AI28: =AH28 -> 0.4 | AJ28: =AI28 -> 0.4 | AK28: =AJ28 -> 0.4 | AL28: =AK28 -> 0.4 | ... AO28: =AN28 -> 0.4 | AP28: =AVERAGE(AD28:AO28) -> 0.4
A29: =ROW() -> 29
A30: =ROW() -> 30 | B30: Werkbare dagen | D30: 21 | E30: 20 | F30: 22 | G30: 20 | H30: 19 | I30: 22 | J30: 23 | K30: 21 | L30: 22 | M30: 22 | N30: 21 | O30: 22 | Q30: 21 | R30: 20 | S30: 22 | T30: 20 | U30: 19 | V30: 22 | W30: 23 | X30: 21 | Y30: 22 | Z30: 22 | AA30: 21 | AB30: 22 | AD30: 21 | AE30: 20 | AF30: 22 | AG30: 20 | AH30: 19 | AI30: 22 | AJ30: 23 | AK30: 21 | AL30: 22 | AM30: 22 | AN30: 21 | AO30: 22
A31: =ROW() -> 31
A32: =ROW() -> 32 | B32: Norm uren klanten Foundation | D32: =Pakketten!$C$19 -> 32 | E32: =Pakketten!$C$19 -> 32 | F32: =Pakketten!$C$19 -> 32 | G32: =Pakketten!$C$19 -> 32 | H32: =Pakketten!$C$19 -> 32 | I32: =Pakketten!$C$19 -> 32 | J32: =Pakketten!$C$19 -> 32 | K32: =Pakketten!$C$19 -> 32 | ... O32: =Pakketten!$C$19 -> 32 | Q32: =Pakketten!$C$19 -> 32 | R32: =Pakketten!$C$19 -> 32 | S32: =Pakketten!$C$19 -> 32 | T32: =Pakketten!$C$19 -> 32 | U32: =Pakketten!$C$19 -> 32 | V32: =Pakketten!$C$19 -> 32 | W32: =Pakketten!$C$19 -> 32 | X32: =Pakketten!$C$19 -> 32 | ... AB32: =Pakketten!$C$19 -> 32 | AD32: =Pakketten!$C$19 -> 32 | AE32: =Pakketten!$C$19 -> 32 | AF32: =Pakketten!$C$19 -> 32 | AG32: =Pakketten!$C$19 -> 32 | AH32: =Pakketten!$C$19 -> 32 | AI32: =Pakketten!$C$19 -> 32 | AJ32: =Pakketten!$C$19 -> 32 | AK32: =Pakketten!$C$19 -> 32 | ... AO32: =Pakketten!$C$19 -> 32
A33: =ROW() -> 33 | B33: Norm uren klanten Growth | D33: =Pakketten!$K$19 -> 132 | E33: =Pakketten!$K$19 -> 132 | F33: =Pakketten!$K$19 -> 132 | G33: =Pakketten!$K$19 -> 132 | H33: =Pakketten!$K$19 -> 132 | I33: =Pakketten!$K$19 -> 132 | J33: =Pakketten!$K$19 -> 132 | K33: =Pakketten!$K$19 -> 132 | ... O33: =Pakketten!$K$19 -> 132 | Q33: =Pakketten!$K$19 -> 132 | R33: =Pakketten!$K$19 -> 132 | S33: =Pakketten!$K$19 -> 132 | T33: =Pakketten!$K$19 -> 132 | U33: =Pakketten!$K$19 -> 132 | V33: =Pakketten!$K$19 -> 132 | W33: =Pakketten!$K$19 -> 132 | X33: =Pakketten!$K$19 -> 132 | ... AB33: =Pakketten!$K$19 -> 132 | AD33: =Pakketten!$K$19 -> 132 | AE33: =Pakketten!$K$19 -> 132 | AF33: =Pakketten!$K$19 -> 132 | AG33: =Pakketten!$K$19 -> 132 | AH33: =Pakketten!$K$19 -> 132 | AI33: =Pakketten!$K$19 -> 132 | AJ33: =Pakketten!$K$19 -> 132 | AK33: =Pakketten!$K$19 -> 132 | ... AO33: =Pakketten!$K$19 -> 132
A34: =ROW() -> 34 | B34: Norm uren klanten Scale | D34: =Pakketten!$S$19 -> 208 | E34: =Pakketten!$S$19 -> 208 | F34: =Pakketten!$S$19 -> 208 | G34: =Pakketten!$S$19 -> 208 | H34: =Pakketten!$S$19 -> 208 | I34: =Pakketten!$S$19 -> 208 | J34: =Pakketten!$S$19 -> 208 | K34: =Pakketten!$S$19 -> 208 | ... O34: =Pakketten!$S$19 -> 208 | Q34: =Pakketten!$S$19 -> 208 | R34: =Pakketten!$S$19 -> 208 | S34: =Pakketten!$S$19 -> 208 | T34: =Pakketten!$S$19 -> 208 | U34: =Pakketten!$S$19 -> 208 | V34: =Pakketten!$S$19 -> 208 | W34: =Pakketten!$S$19 -> 208 | X34: =Pakketten!$S$19 -> 208 | ... AB34: =Pakketten!$S$19 -> 208 | AD34: =Pakketten!$S$19 -> 208 | AE34: =Pakketten!$S$19 -> 208 | AF34: =Pakketten!$S$19 -> 208 | AG34: =Pakketten!$S$19 -> 208 | AH34: =Pakketten!$S$19 -> 208 | AI34: =Pakketten!$S$19 -> 208 | AJ34: =Pakketten!$S$19 -> 208 | AK34: =Pakketten!$S$19 -> 208 | ... AO34: =Pakketten!$S$19 -> 208
A35: =ROW() -> 35
B36: Tarieven
A37: =ROW() -> 37 | B37: C-level tarief | D37: =Pakketten!D10 -> 91 | E37: =D37 -> 91 | F37: =E37 -> 91 | G37: =F37 -> 91 | H37: =G37 -> 91 | I37: =H37 -> 91 | J37: =I37 -> 91 | K37: =J37 -> 91 | L37: =K37 -> 91 | ... O37: =N37 -> 91 | Q37: =O37*1.03 -> 93.73 | R37: =Q37 -> 93.73 | S37: =R37 -> 93.73 | T37: =S37 -> 93.73 | U37: =T37 -> 93.73 | V37: =U37 -> 93.73 | W37: =V37 -> 93.73 | X37: =W37 -> 93.73 | Y37: =X37 -> 93.73 | ... AB37: =AA37 -> 93.73 | AD37: =AB37*1.03 -> 96.5419 | AE37: =AD37 -> 96.5419 | AF37: =AE37 -> 96.5419 | AG37: =AF37 -> 96.5419 | AH37: =AG37 -> 96.5419 | AI37: =AH37 -> 96.5419 | AJ37: =AI37 -> 96.5419 | AK37: =AJ37 -> 96.5419 | AL37: =AK37 -> 96.5419 | ... AO37: =AN37 -> 96.5419
A38: =ROW() -> 38 | B38: Senior tarief | D38: =Pakketten!D12 -> 95.157 | E38: =D38 -> 95.157 | F38: =E38 -> 95.157 | G38: =F38 -> 95.157 | H38: =G38 -> 95.157 | I38: =H38 -> 95.157 | J38: =I38 -> 95.157 | K38: =J38 -> 95.157 | L38: =K38 -> 95.157 | ... O38: =N38 -> 95.157 | Q38: =O38*1.03 -> 98.01171 | R38: =Q38 -> 98.01171 | S38: =R38 -> 98.01171 | T38: =S38 -> 98.01171 | U38: =T38 -> 98.01171 | V38: =U38 -> 98.01171 | W38: =V38 -> 98.01171 | X38: =W38 -> 98.01171 | Y38: =X38 -> 98.01171 | ... AB38: =AA38 -> 98.01171 | AD38: =AB38*1.03 -> 100.95206 | AE38: =AD38 -> 100.95206 | AF38: =AE38 -> 100.95206 | AG38: =AF38 -> 100.95206 | AH38: =AG38 -> 100.95206 | AI38: =AH38 -> 100.95206 | AJ38: =AI38 -> 100.95206 | AK38: =AJ38 -> 100.95206 | AL38: =AK38 -> 100.95206 | ... AO38: =AN38 -> 100.95206
A39: =ROW() -> 39 | B39: - HR partner (Senior-level) tarief | D39: =Pakketten!D14 -> 62.42625 | E39: =D39 -> 62.42625 | F39: =E39 -> 62.42625 | G39: =F39 -> 62.42625 | H39: =G39 -> 62.42625 | I39: =H39 -> 62.42625 | J39: =I39 -> 62.42625 | K39: =J39 -> 62.42625 | L39: =K39 -> 62.42625 | ... O39: =N39 -> 62.42625 | Q39: =O39*1.03 -> 64.299037 | R39: =Q39 -> 64.299037 | S39: =R39 -> 64.299037 | T39: =S39 -> 64.299037 | U39: =T39 -> 64.299037 | V39: =U39 -> 64.299037 | W39: =V39 -> 64.299037 | X39: =W39 -> 64.299037 | Y39: =X39 -> 64.299037 | ... AB39: =AA39 -> 64.299037 | AD39: =AB39*1.03 -> 66.228009 | AE39: =AD39 -> 66.228009 | AF39: =AE39 -> 66.228009 | AG39: =AF39 -> 66.228009 | AH39: =AG39 -> 66.228009 | AI39: =AH39 -> 66.228009 | AJ39: =AI39 -> 66.228009 | AK39: =AJ39 -> 66.228009 | AL39: =AK39 -> 66.228009 | ... AO39: =AN39 -> 66.228009
A40: =ROW() -> 40 | B40: - Finance admin (Senior-level) tarief | D40: =Pakketten!D15 -> 77.666625 | E40: =D40 -> 77.666625 | F40: =E40 -> 77.666625 | G40: =F40 -> 77.666625 | H40: =G40 -> 77.666625 | I40: =H40 -> 77.666625 | J40: =I40 -> 77.666625 | K40: =J40 -> 77.666625 | L40: =K40 -> 77.666625 | ... O40: =N40 -> 77.666625 | Q40: =O40*1.03 -> 79.996624 | R40: =Q40 -> 79.996624 | S40: =R40 -> 79.996624 | T40: =S40 -> 79.996624 | U40: =T40 -> 79.996624 | V40: =U40 -> 79.996624 | W40: =V40 -> 79.996624 | X40: =W40 -> 79.996624 | Y40: =X40 -> 79.996624 | ... AB40: =AA40 -> 79.996624 | AD40: =AB40*1.03 -> 82.396522 | AE40: =AD40 -> 82.396522 | AF40: =AE40 -> 82.396522 | AG40: =AF40 -> 82.396522 | AH40: =AG40 -> 82.396522 | AI40: =AH40 -> 82.396522 | AJ40: =AI40 -> 82.396522 | AK40: =AJ40 -> 82.396522 | AL40: =AK40 -> 82.396522 | ... AO40: =AN40 -> 82.396522
...

Sheet Propositie
B2: Propositie: | C2: Fractional C-Suite + Execution Platform voor purpose-gedreven startups en scale-ups.
B4: Veel founders groeien snel maar missen een sterke finance en operations backbone.
B5: Wij bouwen en runnen je volledige backoffice, finance, HR en commerciële infrastructuur, zodat jij je volledig kunt focussen op groei.
B6: Niet als consultant
B7: Niet als interim
B8: Maar als strategisch operator-partner, van strategie tot executeren
B11: Wanneer ondernemers starten en snel groeien ontstaan uitdagingen:
B13: Finance structuur (strakke processen en administratie)
B14: Cashflow controle
B15: HR structuur
B16: Sales structuur
B17: Organisatiestructuur
B18: Governance
... B38: 2: Operating infrastructure
B39: Finance stack: | F39: Commercial stack: | J39: Operations stack: | N39: HR stack:
B40: AFAS | F40: Hubspot CRM | J40: KPI dashboards | N40: AFAS
B41: Forecasting & Budgetting | F41: sales funnel | J41: interne processen | N41: hiring
B42: Management reporting | F42: marketing funnel | N42: payroll
B43: Finance & business control | N43: HR management
B44: Risk management
B45: Controle framework
B47: 3: Execution & Ownership
B49: We bouwen vanuit de klantstrategie de backbone van de onderneming en laten dit meegroeien met de levensfase van de onderneming
B50: Maar dat is niet alles
B51: We runnen finance, HR, en brengen structuur aan in sales, marketing en operations. Sturen bij waar nodig en zijn actief betrokken als c-level partners.
B54: Waardepropositie vanuit de klant
B56: ✔ Volledige controle over hun cashflow
B57: ✔ Professionele finance structuur
B58: ✔ Schaalbare operationele backbone
B59: ✔ Sales en marketing structuur
B60: ✔ Strategische C-level begeleiding
... B67: rust + controle + versnelling

Sheet Ideale klant
B2: Ideale klantprofiel
B4: 0-100 medewerkers
B5: 0-20m omzet
B6: geen volledig c-level team
B7: founder-led, skin in the game
B8: funding of bootstrap met runway
B9: sterke groeiambitie
B10: onder de rivieren
B11: seed (0-1 jaar)
B12: early (1-2 jaar)
B13: product-market fit (2-5 jaar)
B14: scale up (5-10 jaar)
... B25: agencies

Sheet Pakketten
B2: Foundation | J2: Growth | R2: Scale
B3: Prijs | C3: 6750 | J3: Prijs | K3: 17000 | R3: Prijs | S3: 27000
B4: Startups 2-10 FTE | C4: 0 - 3m bruto-omzet | J4: Startups 10-30 FTE | K4: 1 - 8m bruto-omzet | R4: Startups 30-100 FTE | S4: 6 - 25m bruto-omzet
B5: Typologie bedrijven: Dienstverlening (zonder goederenbeweging), Urencapaciteit, Productiebedrijven, Handelsbedrijven | J5: Typologie bedrijven: Dienstverlening (zonder goederenbeweging), Urencapaciteit, Productiebedrijven, Handelsbedrijven | R5: Typologie bedrijven: Dienstverlening (zonder goederenbeweging), Urencapaciteit, Productiebedrijven, Handelsbedrijven
B6: Voorbeeld: Projectorganisaties, Consultancy, Advies, Software, MSP, Productie, Energie | J6: Voorbeeld: Projectorganisaties, Consultancy, Advies, Software, MSP, Productie, Energie | R6: Voorbeeld: Projectorganisaties, Consultancy, Advies, Software, MSP, Productie, Energie
B8: Maandelijkse inzet | C8: Uren | D8: Tarief KP | E8: Kosten | G8: blendded rate | J8: Maandelijkse inzet | K8: Uren | L8: Tarief KP | M8: Kosten | O8: blendded rate | R8: Maandelijkse inzet | S8: Uren | T8: Tarief KP | U8: Kosten | W8: blendded rate
B10: - CEO (C-level) | C10: 4 | D10: =VLOOKUP($B10,OPEX!$B$2:$Q$12,16,FALSE) -> 91 | E10: =C10*D10 -> 364 | J10: - CEO (C-level) | K10: =C10*2 -> 8 | L10: =VLOOKUP($J10,OPEX!$B$2:$Q$12,16,FALSE) -> 91 | M10: =K10*L10 -> 728 | R10: - CEO (C-level) | S10: =K10*2 -> 16 | T10: =VLOOKUP($R10,OPEX!$B$2:$Q$12,16,FALSE) -> 91 | U10: =S10*T10 -> 1456
B11: - CFO (C-level) | C11: 8 | D11: =VLOOKUP($B11,OPEX!$B$2:$Q$12,16,FALSE) -> 91 | E11: =C11*D11 -> 728 | J11: - CFO (C-level) | K11: =C11*2 -> 16 | L11: =VLOOKUP($J11,OPEX!$B$2:$Q$12,16,FALSE) -> 91 | M11: =K11*L11 -> 1456 | R11: - CFO (C-level) | S11: =K11*2 -> 32 | T11: =VLOOKUP($R11,OPEX!$B$2:$Q$12,16,FALSE) -> 91 | U11: =S11*T11 -> 2912
B12: - CMO (Senior-level) | C12: 6 | D12: =VLOOKUP($B12,OPEX!$B$2:$Q$12,16,FALSE) -> 95.157 | E12: =C12*D12 -> 570.942 | J12: - CMO (Senior-level) | K12: =C12*4 -> 24 | L12: =VLOOKUP($J12,OPEX!$B$2:$Q$12,16,FALSE) -> 95.157 | M12: =K12*L12 -> 2283.768 | R12: - CMO (Senior-level) | S12: =K12*1.5 -> 36 | T12: =VLOOKUP($R12,OPEX!$B$2:$Q$12,16,FALSE) -> 95.157 | U12: =S12*T12 -> 3425.652
B13: - CTO (Senior-level) | C13: 6 | D13: =VLOOKUP($B13,OPEX!$B$2:$Q$12,16,FALSE) -> 95.157 | E13: =C13*D13 -> 570.942 | J13: - CTO (Senior-level) | K13: =C13*4 -> 24 | L13: =VLOOKUP($J13,OPEX!$B$2:$Q$12,16,FALSE) -> 95.157 | M13: =K13*L13 -> 2283.768 | R13: - CTO (Senior-level) | S13: =K13*1.5 -> 36 | T13: =VLOOKUP($R13,OPEX!$B$2:$Q$12,16,FALSE) -> 95.157 | U13: =S13*T13 -> 3425.652
B14: - HR partner (Senior-level) | C14: 8 | D14: =VLOOKUP($B14,OPEX!$B$2:$Q$12,16,FALSE) -> 62.42625 | E14: =C14*D14 -> 499.41 | J14: - HR partner (Senior-level) | K14: =C14*3 -> 24 | L14: =VLOOKUP($J14,OPEX!$B$2:$Q$12,16,FALSE) -> 62.42625 | M14: =K14*L14 -> 1498.23 | R14: - HR partner (Senior-level) | S14: =K14*1.5 -> 36 | T14: =VLOOKUP($R14,OPEX!$B$2:$Q$12,16,FALSE) -> 62.42625 | U14: =S14*T14 -> 2247.345
B15: - Finance admin (Sedior-level) | C15: 12 | D15: =VLOOKUP($B15,OPEX!$B$2:$Q$12,16,FALSE) -> 77.666625 | E15: =C15*D15 -> 931.9995 | J15: - Finance admin (Sedior-level) | K15: =C15*1.5 -> 18 | L15: =VLOOKUP($J15,OPEX!$B$2:$Q$12,16,FALSE) -> 77.666625 | M15: =K15*L15 -> 1397.9992 | R15: - Finance admin (Sedior-level) | S15: 24 | T15: =VLOOKUP($R15,OPEX!$B$2:$Q$12,16,FALSE) -> 77.666625 | U15: =S15*T15 -> 1863.999
B16: - HR admin (Medior-level) | C16: 0 | D16: =VLOOKUP($B16,OPEX!$B$2:$Q$12,16,FALSE) -> 50.391 | E16: =C16*D16 -> 0 | J16: - HR admin (Medior-level) | K16: 8 | L16: =VLOOKUP($J16,OPEX!$B$2:$Q$12,16,FALSE) -> 50.391 | M16: =K16*L16 -> 403.128 | R16: - HR admin (Medior-level) | S16: =K16*2 -> 16 | T16: =VLOOKUP($R16,OPEX!$B$2:$Q$12,16,FALSE) -> 50.391 | U16: =S16*T16 -> 806.256
B17: - Backoffice support (Junior-level) | C17: 20 | D17: =VLOOKUP($B17,OPEX!$B$2:$Q$12,16,FALSE) -> 34.60575 | E17: =C17*D17 -> 692.115 | J17: - Backoffice support (Junior-level) | K17: =C17*1.5 -> 30 | L17: =VLOOKUP($J17,OPEX!$B$2:$Q$12,16,FALSE) -> 34.60575 | M17: =K17*L17 -> 1038.1725 | R17: - Backoffice support (Junior-level) | S17: =K17*2 -> 60 | T17: =VLOOKUP($R17,OPEX!$B$2:$Q$12,16,FALSE) -> 34.60575 | U17: =S17*T17 -> 2076.345
B18: - Data engineer (Medior-level) | C18: 0 | D18: =VLOOKUP($B18,OPEX!$B$2:$Q$12,16,FALSE) -> 50.971125 | E18: =C18*D18 -> 0 | J18: - Data engineer (Medior-level) | K18: 4 | L18: =VLOOKUP($J18,OPEX!$B$2:$Q$12,16,FALSE) -> 50.971125 | M18: =K18*L18 -> 203.8845 | R18: - Data engineer (Medior-level) | S18: 8 | T18: =VLOOKUP($R18,OPEX!$B$2:$Q$12,16,FALSE) -> 50.971125
C19: =SUM(C12:C16) -> 32 | E19: =SUM(E10:E18) -> 4357.4085 | G19: =E19/C19 -> 136.16902 | K19: =SUM(K12:K18) -> 132 | M19: =SUM(M10:M18) -> 11292.95 | O19: =M19/K19 -> 85.552653 | S19: =SUM(S12:S17) -> 208 | U19: =SUM(U10:U18) -> 18213.249 | W19: =U19/S19 -> 87.563697
B21: Software | J21: Software | R21: Software
B22: AFAS | C22: 1 | D22: 300 | E22: =C22*D22 -> 300 | J22: AFAS | K22: 1 | L22: 300 | M22: =K22*L22 -> 300 | R22: AFAS | S22: 1 | T22: 300 | U22: =S22*T22 -> 300
B23: AFAS licenties | C23: 10 | D23: 30 | E23: =C23*D23 -> 300 | J23: AFAS licenties | K23: 30 | L23: 30 | M23: =K23*L23 -> 900 | R23: AFAS licenties | S23: 75 | T23: 30 | U23: =S23*T23 -> 2250
B24: Hubspot | C24: 1 | D24: 350 | E24: =C24*D24 -> 350 | J24: Hubspot | K24: 2 | L24: 350 | M24: =K24*L24 -> 700 | R24: Hubspot | S24: 2 | T24: 350 | U24: =S24*T24 -> 700
E25: =SUM(E22:E24) -> 950 | M25: =SUM(M22:M24) -> 1900 | U25: =SUM(U22:U24) -> 3250
B27: Totaal | E27: =E19+E25 -> 5307.4085 | J27: Totaal | M27: =M19+M25 -> 13192.95 | R27: Totaal | U27: =U19+U25 -> 21463.249
B28: Overhead (25%) | D28: 0.25 | E28: =D28*E27 -> 1326.8521 | J28: Overhead (25%) | L28: 0.25 | M28: =L28*M27 -> 3298.2376 | R28: Overhead (25%) | T28: 0.25 | U28: =T28*U27 -> 5365.8122
B30: Totaal inclusief overhead | E30: =E27+E28 -> 6634.2606 | J30: Totaal inclusief overhead | M30: =M27+M28 -> 16491.188 | R30: Totaal inclusief overhead | U30: =U27+U28 -> 26829.061
B32: Marge | E32: =C3-E30 -> 115.73938 | J32: Marge | M32: =K3-M30 -> 508.81219 | R32: Marge | U32: =S3-U30 -> 170.93875
B33: Marge% | E33: =E32/C3 -> 0.017146574 | J33: Marge% | M33: =M32/K3 -> 0.029930129 | R33: Marge% | U33: =U32/S3 -> 0.0063310648
B36: Add-ons | J36: Add-ons | R36: Add-ons
B37: - API koppelingen | J37: - API koppelingen | R37: - API koppelingen
B38: - MS stack | J38: - MS stack | R38: - MS stack
B39: - DaaS | J39: - DaaS | R39: - DaaS
B40: - Data platform en dashboarding | J40: - Data platform en dashboarding | R40: - Data platform en dashboarding
B41: - IT beheer | J41: - IT beheer | R41: - IT beheer
B45: Deliverables | J45: Deliverables | R45: Deliverables
B46: - Modern en altijd up-to-date ingerichte backbone, IT omgeving en administratie gebaseerd op AFAS & Hubspot | J46: - Modern en altijd up-to-date ingerichte backbone, IT omgeving en administratie gebaseerd op AFAS & Hubspot | R46: - Modern en altijd up-to-date ingerichte backbone, IT omgeving en administratie gebaseerd op AFAS & Hubspot
B47: - Professionele, effectief en efficiente processen voor finance, HR, sales en eventueel met marketing, payroll, projecten + ordermanagement | J47: - Professionele, effectief en efficiente processen voor finance, HR, sales en eventueel met marketing, payroll, projecten + ordermanagement | R47: - Professionele, effectief en efficiente processen voor finance, HR, sales en eventueel met marketing, payroll, projecten + ordermanagement
B48: - Financiele administratie optioneel salarisadministratie, projectadministratie, voorraadadministratie | J48: - Dashboarding en KPIs | R48: - Dashboarding en KPIs
B49: - Maandafsluiting en rapportage | J49: - Financiele administratie optioneel salarisadministratie, projectadministratie, voorraadadministratie | R49: - Financiele administratie optioneel salarisadministratie, projectadministratie, voorraadadministratie
B50: - Forecast & Budget inclusief cash forecast | J50: - Maandafsluiting en rapportages | R50: - Maandafsluiting en rapportages
... B55: - AV sessies (max 4x per jaar) | J55: - On- en offboarding medewerkers | R55: - On- en offboarding medewerkers
J56: - AV sessies (max 4x per jaar) | R56: - AV sessies (max 4x per jaar)
...

Sheet OPEX
N1: =2080 -> 2080 | O1: 1600
B2: Personeelskosten | C2: FTE | D2: Management fee | E2: Brutosalaris | F2: Vakantiegeld | G2: Bonus | H2: Pensioen | I2: Soc. Lasten | J2: Auto, vergoeding | K2: Brandstof | L2: Overige onkosten | M2: Totaal | N2: Uren per maand | O2: Werkbare declarabele uren per maand | P2: Uurloon | Q2: Uurloon werkbaar
B4: - CEO (C-level) | C4: 1 | D4: 10000 | G4: =D4/12 -> 833.33333 | J4: 1000 | K4: 200 | L4: 100 | M4: =SUM(D4:L4) -> 12133.333 | N4: =N$1/12 -> 173.33333 | O4: =O$1/12 -> 133.33333 | P4: =M4/N4 -> 70 | Q4: =M4/O4 -> 91
B5: - CFO (C-level) | C5: 1 | D5: 10000 | G5: =D5/12 -> 833.33333 | J5: 1000 | K5: 200 | L5: 100 | M5: =SUM(D5:L5) -> 12133.333 | N5: =N$1/12 -> 173.33333 | O5: =O$1/12 -> 133.33333 | P5: =M5/N5 -> 70 | Q5: =M5/O5 -> 91
B6: - CMO (Senior-level) | C6: 1 | E6: 8000 | F6: =E6*0.08 -> 640 | G6: =E6*1/12 -> 666.66667 | H6: =0.08*E6 -> 640 | I6: =0.17*SUM(E6:H6) -> 1690.9333 | J6: 850 | K6: 150 | L6: 50 | M6: =SUM(D6:L6) -> 12687.6 | N6: =N$1/12 -> 173.33333 | O6: =O$1/12 -> 133.33333 | P6: =M6/N6 -> 73.197692 | Q6: =M6/O6 -> 95.157
B7: - CTO (Senior-level) | C7: 1 | E7: 8000 | F7: =E7*0.08 -> 640 | G7: =E7*1/12 -> 666.66667 | H7: =0.08*E7 -> 640 | I7: =0.17*SUM(E7:H7) -> 1690.9333 | J7: 850 | K7: 150 | L7: 50 | M7: =SUM(D7:L7) -> 12687.6 | N7: =N$1/12 -> 173.33333 | O7: =O$1/12 -> 133.33333 | P7: =M7/N7 -> 73.197692 | Q7: =M7/O7 -> 95.157
B8: - HR partner (Senior-level) | C8: 1 | E8: 5000 | F8: =E8*0.08 -> 400 | G8: =E8*1/12 -> 416.66667 | H8: =0.08*E8 -> 400 | I8: =0.17*SUM(E8:H8) -> 1056.8333 | J8: 850 | K8: 150 | L8: 50 | M8: =SUM(D8:L8) -> 8323.5 | N8: =N$1/12 -> 173.33333 | O8: =O$1/12 -> 133.33333 | P8: =M8/N8 -> 48.020192 | Q8: =M8/O8 -> 62.42625
B9: - Finance admin (Sedior-level) | C9: 1 | E9: 6500 | F9: =E9*0.08 -> 520 | G9: =E9*1/12 -> 541.66667 | H9: =0.08*E9 -> 520 | I9: =0.17*SUM(E9:H9) -> 1373.8833 | J9: 700 | K9: 150 | L9: 50 | M9: =SUM(D9:L9) -> 10355.55 | N9: =N$1/12 -> 173.33333 | O9: =O$1/12 -> 133.33333 | P9: =M9/N9 -> 59.743558 | Q9: =M9/O9 -> 77.666625
B10: - HR admin (Medior-level) | C10: 1 | E10: 4000 | F10: =E10*0.08 -> 320 | G10: =E10*1/12 -> 333.33333 | H10: =0.08*E10 -> 320 | I10: =0.17*SUM(E10:H10) -> 845.46667 | J10: 700 | K10: 150 | L10: 50 | M10: =SUM(D10:L10) -> 6718.8 | N10: =N$1/12 -> 173.33333 | O10: =O$1/12 -> 133.33333 | P10: =M10/N10 -> 38.762308 | Q10: =M10/O10 -> 50.391
B11: - Backoffice support (Junior-level) | C11: 1 | E11: 3000 | F11: =E11*0.08 -> 240 | G11: =E11*1/12 -> 250 | H11: =0.08*E11 -> 240 | I11: =0.17*SUM(E11:H11) -> 634.1 | J11: 200 | L11: 50 | M11: =SUM(D11:L11) -> 4614.1 | N11: =N$1/12 -> 173.33333 | O11: =O$1/12 -> 133.33333 | P11: =M11/N11 -> 26.619808 | Q11: =M11/O11 -> 34.60575
B12: - Data engineer (Medior-level) | C12: 1 | E12: 4500 | F12: =E12*0.08 -> 360 | G12: =E12*1/12 -> 375 | H12: =0.08*E12 -> 360 | I12: =0.17*SUM(E12:H12) -> 951.15 | J12: 200 | L12: 50 | M12: =SUM(D12:L12) -> 6796.15 | N12: =N$1/12 -> 173.33333 | O12: =O$1/12 -> 133.33333 | P12: =M12/N12 -> 39.208558 | Q12: =M12/O12 -> 50.971125
D13: =SUM(D4:D12) -> 20000 | E13: =SUM(E4:E12) -> 39000 | F13: =SUM(F4:F12) -> 3120 | G13: =SUM(G4:G12) -> 4916.6667 | H13: =SUM(H4:H12) -> 3120 | I13: =SUM(I4:I12) -> 8243.3 | J13: =SUM(J4:J12) -> 6350 | K13: =SUM(K4:K12) -> 1150 | ... M13: =SUM(M4:M12) -> 86449.967
D15: 2026-01 | E15: 2026-02 | F15: 2026-03 | G15: 2026-04 | H15: 2026-05 | I15: 2026-06 | J15: 2026-07 | K15: 2026-08 | L15: 2026-09 | M15: 2026-10 | N15: 2026-11 | O15: 2026-12 | Q15: 2027-01 | R15: 2027-02 | S15: 2027-03 | T15: 2027-04 | U15: 2027-05 | V15: 2027-06 | W15: 2027-07 | X15: 2027-08 | Y15: 2027-09 | Z15: 2027-10 | AA15: 2027-11 | AB15: 2027-12 | AD15: 2027-01 | AE15: 2027-02 | AF15: 2027-03 | AG15: 2027-04 | AH15: 2027-05 | AI15: 2027-06 | AJ15: 2027-07 | AK15: 2027-08 | AL15: 2027-09 | AM15: 2027-10 | AN15: 2027-11 | AO15: 2027-12
B17: - CEO (C-level) | D17: 0.2 | E17: 0.2 | F17: 0.2 | G17: 0.2 | H17: 0.2 | I17: 0.2 | J17: 0.2 | K17: 0.2 | L17: 0.2 | M17: 0.2 | N17: 0.2 | O17: 0.2 | Q17: =RFF!Q20 -> 0.5 | R17: =RFF!R20 -> 0.5 | S17: =RFF!S20 -> 0.5 | T17: =RFF!T20 -> 0.6 | U17: =RFF!U20 -> 0.6 | V17: =RFF!V20 -> 0.6 | W17: =RFF!W20 -> 0.6 | X17: =RFF!X20 -> 0.6 | ... AB17: =RFF!AB20 -> 0.8 | AD17: =RFF!AD20 -> 1.4 | AE17: =RFF!AE20 -> 1.4 | AF17: =RFF!AF20 -> 1.4 | AG17: =RFF!AG20 -> 1.4 | AH17: =RFF!AH20 -> 1.4 | AI17: =RFF!AI20 -> 1.4 | AJ17: =RFF!AJ20 -> 1.4 | AK17: =RFF!AK20 -> 1.4 | ... AO17: =RFF!AO20 -> 1.6
B18: - CFO (C-level) | D18: 0.6 | E18: 0.6 | F18: 0.6 | G18: 0.6 | H18: 0.6 | I18: 0.6 | J18: 0.6 | K18: 0.6 | L18: 0.6 | M18: 0.6 | N18: 0.6 | O18: 0.6 | Q18: =RFF!Q21 -> 0.8 | R18: =RFF!R21 -> 0.8 | S18: =RFF!S21 -> 0.8 | T18: =RFF!T21 -> 1 | U18: =RFF!U21 -> 1.4 | V18: =RFF!V21 -> 1.4 | W18: =RFF!W21 -> 1.4 | X18: =RFF!X21 -> 1.4 | ... AB18: =RFF!AB21 -> 1.4 | AD18: =RFF!AD21 -> 2 | AE18: =RFF!AE21 -> 2 | AF18: =RFF!AF21 -> 2 | AG18: =RFF!AG21 -> 2.2 | AH18: =RFF!AH21 -> 2.2 | AI18: =RFF!AI21 -> 2.2 | AJ18: =RFF!AJ21 -> 2.2 | AK18: =RFF!AK21 -> 2.2 | ... AO18: =RFF!AO21 -> 2.6
B19: - CMO (Senior-level) | J19: 0.4 | K19: 0.4 | L19: 0.4 | M19: 0.4 | N19: 0.4 | O19: 0.4 | Q19: =RFF!Q22 -> 0.8 | R19: =RFF!R22 -> 0.8 | S19: =RFF!S22 -> 0.8 | T19: =RFF!T22 -> 1 | U19: =RFF!U22 -> 1.2 | V19: =RFF!V22 -> 1.2 | W19: =RFF!W22 -> 1.2 | X19: =RFF!X22 -> 1.2 | ... AB19: =RFF!AB22 -> 1.4 | AD19: =RFF!AD22 -> 2 | AE19: =RFF!AE22 -> 2 | AF19: =RFF!AF22 -> 2 | AG19: =RFF!AG22 -> 2.2 | AH19: =RFF!AH22 -> 2.2 | AI19: =RFF!AI22 -> 2.2 | AJ19: =RFF!AJ22 -> 2.2 | AK19: =RFF!AK22 -> 2.2 | ... AO19: =RFF!AO22 -> 2.6
B20: - CTO (Senior-level) | J20: 0.4 | K20: 0.4 | L20: 0.4 | M20: 0.4 | N20: 0.4 | O20: 0.4 | Q20: =RFF!Q23 -> 0.8 | R20: =RFF!R23 -> 0.8 | S20: =RFF!S23 -> 0.8 | T20: =RFF!T23 -> 1 | U20: =RFF!U23 -> 1.2 | V20: =RFF!V23 -> 1.2 | W20: =RFF!W23 -> 1.2 | X20: =RFF!X23 -> 1.2 | ... AB20: =RFF!AB23 -> 1.4 | AD20: =RFF!AD23 -> 2 | AE20: =RFF!AE23 -> 2 | AF20: =RFF!AF23 -> 2 | AG20: =RFF!AG23 -> 2.4 | AH20: =RFF!AH23 -> 2.4 | AI20: =RFF!AI23 -> 2.4 | AJ20: =RFF!AJ23 -> 2.4 | AK20: =RFF!AK23 -> 2.4 | ... AO20: =RFF!AO23 -> 2.6
B21: - HR partner (Senior-level) | J21: 0.4 | K21: 0.4 | L21: 0.4 | M21: 0.4 | N21: 0.4 | O21: 0.4 | Q21: =RFF!Q24 -> 0.8 | R21: =RFF!R24 -> 0.8 | S21: =RFF!S24 -> 0.8 | T21: =RFF!T24 -> 1.4 | U21: =RFF!U24 -> 1.4 | V21: =RFF!V24 -> 1.4 | W21: =RFF!W24 -> 1.4 | X21: =RFF!X24 -> 1.4 | ... AB21: =RFF!AB24 -> 1.4 | AD21: =RFF!AD24 -> 2 | AE21: =RFF!AE24 -> 2 | AF21: =RFF!AF24 -> 2 | AG21: =RFF!AG24 -> 2.4 | AH21: =RFF!AH24 -> 2.4 | AI21: =RFF!AI24 -> 2.4 | AJ21: =RFF!AJ24 -> 2.4 | AK21: =RFF!AK24 -> 2.4 | ... AO21: =RFF!AO24 -> 2.6
B22: - Finance admin (Sedior-level) | D22: 0.4 | E22: 0.4 | F22: 0.4 | G22: 0.4 | H22: 0.4 | I22: 0.4 | J22: 1.4 | K22: 1.4 | L22: 1.4 | M22: 1.4 | N22: 1.4 | O22: 1.4 | Q22: =RFF!Q25 -> 1 | R22: =RFF!R25 -> 1 | S22: =RFF!S25 -> 1 | T22: =RFF!T25 -> 1.4 | U22: =RFF!U25 -> 1.4 | V22: =RFF!V25 -> 1.4 | W22: =RFF!W25 -> 1.4 | X22: =RFF!X25 -> 1.4 | ... AB22: =RFF!AB25 -> 1.4 | AD22: =RFF!AD25 -> 2 | AE22: =RFF!AE25 -> 2 | AF22: =RFF!AF25 -> 2 | AG22: =RFF!AG25 -> 2.4 | AH22: =RFF!AH25 -> 2.4 | AI22: =RFF!AI25 -> 2.4 | AJ22: =RFF!AJ25 -> 2.4 | AK22: =RFF!AK25 -> 2.4 | ... AO22: =RFF!AO25 -> 2.6
B23: - HR admin (Medior-level) | Q23: =RFF!Q26 -> 0 | R23: =RFF!R26 -> 0 | S23: =RFF!S26 -> 0 | T23: =RFF!T26 -> 0 | U23: =RFF!U26 -> 0 | V23: =RFF!V26 -> 0 | W23: =RFF!W26 -> 0 | X23: =RFF!X26 -> 0 | ... AB23: =RFF!AB26 -> 0 | AD23: =RFF!AD26 -> 0 | AE23: =RFF!AE26 -> 0 | AF23: =RFF!AF26 -> 0 | AG23: =RFF!AG26 -> 0 | AH23: =RFF!AH26 -> 0 | AI23: =RFF!AI26 -> 0 | AJ23: =RFF!AJ26 -> 0 | AK23: =RFF!AK26 -> 0 | ... AO23: =RFF!AO26 -> 0
B24: - Backoffice support (Junior-level) | J24: 0.4 | K24: 0.4 | L24: 1 | M24: 1 | N24: 1 | O24: 1 | Q24: =RFF!Q27 -> 1.6 | R24: =RFF!R27 -> 1.6 | S24: =RFF!S27 -> 1.6 | T24: =RFF!T27 -> 2 | U24: =RFF!U27 -> 2.4 | V24: =RFF!V27 -> 2.4 | W24: =RFF!W27 -> 2.4 | X24: =RFF!X27 -> 2.4 | ... AB24: =RFF!AB27 -> 3 | AD24: =RFF!AD27 -> 4 | AE24: =RFF!AE27 -> 4 | AF24: =RFF!AF27 -> 4 | AG24: =RFF!AG27 -> 4.4 | AH24: =RFF!AH27 -> 4.4 | AI24: =RFF!AI27 -> 4.4 | AJ24: =RFF!AJ27 -> 4.4 | AK24: =RFF!AK27 -> 4.4 | ... AO24: =RFF!AO27 -> 4.6
B25: - Data engineer (Medior-level) | J25: 0.4 | K25: 0.4 | L25: 0.4 | M25: 0.4 | N25: 0.4 | O25: 0.4 | Q25: =RFF!Q28 -> 0.4 | R25: =RFF!R28 -> 0.4 | S25: =RFF!S28 -> 0.4 | T25: =RFF!T28 -> 0.4 | U25: =RFF!U28 -> 0.4 | V25: =RFF!V28 -> 0.4 | W25: =RFF!W28 -> 0.4 | X25: =RFF!X28 -> 0.4 | ... AB25: =RFF!AB28 -> 0.4 | AD25: =RFF!AD28 -> 0.4 | AE25: =RFF!AE28 -> 0.4 | AF25: =RFF!AF28 -> 0.4 | AG25: =RFF!AG28 -> 0.4 | AH25: =RFF!AH28 -> 0.4 | AI25: =RFF!AI28 -> 0.4 | AJ25: =RFF!AJ28 -> 0.4 | AK25: =RFF!AK28 -> 0.4 | ... AO25: =RFF!AO28 -> 0.4
B28: Personeelskosten | D28: =SUM(D29:D38) -> 13933.127 | E28: =SUM(E29:E38) -> 13933.127 | F28: =SUM(F29:F38) -> 13933.127 | G28: =SUM(G29:G38) -> 13933.127 | H28: =SUM(H29:H38) -> 13933.127 | I28: =SUM(I29:I38) -> 13933.127 | J28: =SUM(J29:J38) -> 42912.217 | K28: =SUM(K29:K38) -> 42912.217 | ... O28: =SUM(O29:O38) -> 45738.997 | Q28: =SUM(Q29:Q38) -> 65524.052 | R28: =SUM(R29:R38) -> 65524.052 | S28: =SUM(S29:S38) -> 65524.052 | T28: =SUM(T29:T38) -> 85998.682 | U28: =SUM(U29:U38) -> 98121.553 | V28: =SUM(V29:V38) -> 98121.553 | W28: =SUM(W29:W38) -> 98121.553 | X28: =SUM(X29:X38) -> 98121.553 | ... AB28: =SUM(AB29:AB38) -> 108781.78 | AD28: =SUM(AD29:AD38) -> 155920.19 | AE28: =SUM(AE29:AE38) -> 155920.19 | AF28: =SUM(AF29:AF38) -> 155920.19 | AG28: =SUM(AG29:AG38) -> 176098.01 | AH28: =SUM(AH29:AH38) -> 176098.01 | AI28: =SUM(AI29:AI38) -> 176098.01 | AJ28: =SUM(AJ29:AJ38) -> 176098.01 | AK28: =SUM(AK29:AK38) -> 176098.01 | ... AO28: =SUM(AO29:AO38) -> 196257.2
B29: Brutosalarissen | D29: =SUMPRODUCT(D$17:D$25,$E4:$E12) -> 2600 | E29: =SUMPRODUCT(E$17:E$25,$E4:$E12) -> 2600 | F29: =SUMPRODUCT(F$17:F$25,$E4:$E12) -> 2600 | G29: =SUMPRODUCT(G$17:G$25,$E4:$E12) -> 2600 | H29: =SUMPRODUCT(H$17:H$25,$E4:$E12) -> 2600 | I29: =SUMPRODUCT(I$17:I$25,$E4:$E12) -> 2600 | J29: =SUMPRODUCT(J$17:J$25,$E4:$E12) -> 20500 | K29: =SUMPRODUCT(K$17:K$25,$E4:$E12) -> 20500 | ... O29: =SUMPRODUCT(O$17:O$25,$E4:$E12) -> 22300 | Q29: =SUMPRODUCT(Q$17:Q$25,$E4:$E12)*1.03 -> 30797 | R29: =SUMPRODUCT(R$17:R$25,$E4:$E12)*1.03 -> 30797 | S29: =SUMPRODUCT(S$17:S$25,$E4:$E12)*1.03 -> 30797 | T29: =SUMPRODUCT(T$17:T$25,$E4:$E12)*1.03 -> 41097 | U29: =SUMPRODUCT(U$17:U$25,$E4:$E12)*1.03 -> 45629 | V29: =SUMPRODUCT(V$17:V$25,$E4:$E12)*1.03 -> 45629 | W29: =SUMPRODUCT(W$17:W$25,$E4:$E12)*1.03 -> 45629 | X29: =SUMPRODUCT(X$17:X$25,$E4:$E12)*1.03 -> 45629 | ... AB29: =SUMPRODUCT(AB$17:AB$25,$E4:$E12)*1.03 -> 50779 | AD29: =SUMPRODUCT(AD$17:AD$25,$E4:$E12)*1.03 -> 70864 | AE29: =SUMPRODUCT(AE$17:AE$25,$E4:$E12)*1.03 -> 70864 | AF29: =SUMPRODUCT(AF$17:AF$25,$E4:$E12)*1.03 -> 70864 | AG29: =SUMPRODUCT(AG$17:AG$25,$E4:$E12)*1.03 -> 81782 | AH29: =SUMPRODUCT(AH$17:AH$25,$E4:$E12)*1.03 -> 81782 | AI29: =SUMPRODUCT(AI$17:AI$25,$E4:$E12)*1.03 -> 81782 | AJ29: =SUMPRODUCT(AJ$17:AJ$25,$E4:$E12)*1.03 -> 81782 | AK29: =SUMPRODUCT(AK$17:AK$25,$E4:$E12)*1.03 -> 81782 | ... AO29: =SUMPRODUCT(AO$17:AO$25,$E4:$E12)*1.03 -> 89713
B30: Vakantiegeld | D30: =SUMPRODUCT(D$17:D$25,$F4:$F12) -> 208 | E30: =SUMPRODUCT(E$17:E$25,$F4:$F12) -> 208 | F30: =SUMPRODUCT(F$17:F$25,$F4:$F12) -> 208 | G30: =SUMPRODUCT(G$17:G$25,$F4:$F12) -> 208 | H30: =SUMPRODUCT(H$17:H$25,$F4:$F12) -> 208 | I30: =SUMPRODUCT(I$17:I$25,$F4:$F12) -> 208 | J30: =SUMPRODUCT(J$17:J$25,$F4:$F12) -> 1640 | K30: =SUMPRODUCT(K$17:K$25,$F4:$F12) -> 1640 | ... O30: =SUMPRODUCT(O$17:O$25,$F4:$F12) -> 1784 | Q30: =SUMPRODUCT(Q$17:Q$25,$F4:$F12)*1.03 -> 2463.76 | R30: =SUMPRODUCT(R$17:R$25,$F4:$F12)*1.03 -> 2463.76 | S30: =SUMPRODUCT(S$17:S$25,$F4:$F12)*1.03 -> 2463.76 | T30: =SUMPRODUCT(T$17:T$25,$F4:$F12)*1.03 -> 3287.76 | U30: =SUMPRODUCT(U$17:U$25,$F4:$F12)*1.03 -> 3650.32 | V30: =SUMPRODUCT(V$17:V$25,$F4:$F12)*1.03 -> 3650.32 | W30: =SUMPRODUCT(W$17:W$25,$F4:$F12)*1.03 -> 3650.32 | X30: =SUMPRODUCT(X$17:X$25,$F4:$F12)*1.03 -> 3650.32 | ... AB30: =SUMPRODUCT(AB$17:AB$25,$F4:$F12)*1.03 -> 4062.32 | AD30: =SUMPRODUCT(AD$17:AD$25,$F4:$F12)*1.03 -> 5669.12 | AE30: =SUMPRODUCT(AE$17:AE$25,$F4:$F12)*1.03 -> 5669.12 | AF30: =SUMPRODUCT(AF$17:AF$25,$F4:$F12)*1.03 -> 5669.12 | AG30: =SUMPRODUCT(AG$17:AG$25,$F4:$F12)*1.03 -> 6542.56 | AH30: =SUMPRODUCT(AH$17:AH$25,$F4:$F12)*1.03 -> 6542.56 | AI30: =SUMPRODUCT(AI$17:AI$25,$F4:$F12)*1.03 -> 6542.56 | AJ30: =SUMPRODUCT(AJ$17:AJ$25,$F4:$F12)*1.03 -> 6542.56 | AK30: =SUMPRODUCT(AK$17:AK$25,$F4:$F12)*1.03 -> 6542.56 | ... AO30: =SUMPRODUCT(AO$17:AO$25,$F4:$F12)*1.03 -> 7177.04
B31: Bonussen | D31: =SUMPRODUCT(D$17:D$25,$G4:$G12) -> 883.33333 | E31: =SUMPRODUCT(E$17:E$25,$G4:$G12) -> 883.33333 | F31: =SUMPRODUCT(F$17:F$25,$G4:$G12) -> 883.33333 | G31: =SUMPRODUCT(G$17:G$25,$G4:$G12) -> 883.33333 | H31: =SUMPRODUCT(H$17:H$25,$G4:$G12) -> 883.33333 | I31: =SUMPRODUCT(I$17:I$25,$G4:$G12) -> 883.33333 | J31: =SUMPRODUCT(J$17:J$25,$G4:$G12) -> 2375 | K31: =SUMPRODUCT(K$17:K$25,$G4:$G12) -> 2375 | ... O31: =SUMPRODUCT(O$17:O$25,$G4:$G12) -> 2525 | Q31: =SUMPRODUCT(Q$17:Q$25,$G4:$G12)*1.03 -> 3682.25 | R31: =SUMPRODUCT(R$17:R$25,$G4:$G12)*1.03 -> 3682.25 | S31: =SUMPRODUCT(S$17:S$25,$G4:$G12)*1.03 -> 3682.25 | T31: =SUMPRODUCT(T$17:T$25,$G4:$G12)*1.03 -> 4798.0833 | U31: =SUMPRODUCT(U$17:U$25,$G4:$G12)*1.03 -> 5519.0833 | V31: =SUMPRODUCT(V$17:V$25,$G4:$G12)*1.03 -> 5519.0833 | W31: =SUMPRODUCT(W$17:W$25,$G4:$G12)*1.03 -> 5519.0833 | X31: =SUMPRODUCT(X$17:X$25,$G4:$G12)*1.03 -> 5519.0833 | ... AB31: =SUMPRODUCT(AB$17:AB$25,$G4:$G12)*1.03 -> 6119.9167 | AD31: =SUMPRODUCT(AD$17:AD$25,$G4:$G12)*1.03 -> 8823.6667 | AE31: =SUMPRODUCT(AE$17:AE$25,$G4:$G12)*1.03 -> 8823.6667 | AF31: =SUMPRODUCT(AF$17:AF$25,$G4:$G12)*1.03 -> 8823.6667 | AG31: =SUMPRODUCT(AG$17:AG$25,$G4:$G12)*1.03 -> 9905.1667 | AH31: =SUMPRODUCT(AH$17:AH$25,$G4:$G12)*1.03 -> 9905.1667 | AI31: =SUMPRODUCT(AI$17:AI$25,$G4:$G12)*1.03 -> 9905.1667 | AJ31: =SUMPRODUCT(AJ$17:AJ$25,$G4:$G12)*1.03 -> 9905.1667 | AK31: =SUMPRODUCT(AK$17:AK$25,$G4:$G12)*1.03 -> 9905.1667 | ... AO31: =SUMPRODUCT(AO$17:AO$25,$G4:$G12)*1.03 -> 11081.083
B32: Pensioen | D32: =SUMPRODUCT(D$17:D$25,$H4:$H12) -> 208 | E32: =SUMPRODUCT(E$17:E$25,$H4:$H12) -> 208 | F32: =SUMPRODUCT(F$17:F$25,$H4:$H12) -> 208 | G32: =SUMPRODUCT(G$17:G$25,$H4:$H12) -> 208 | H32: =SUMPRODUCT(H$17:H$25,$H4:$H12) -> 208 | I32: =SUMPRODUCT(I$17:I$25,$H4:$H12) -> 208 | J32: =SUMPRODUCT(J$17:J$25,$H4:$H12) -> 1640 | K32: =SUMPRODUCT(K$17:K$25,$H4:$H12) -> 1640 | ... O32: =SUMPRODUCT(O$17:O$25,$H4:$H12) -> 1784 | Q32: =SUMPRODUCT(Q$17:Q$25,$H4:$H12)*1.03 -> 2463.76 | R32: =SUMPRODUCT(R$17:R$25,$H4:$H12)*1.03 -> 2463.76 | S32: =SUMPRODUCT(S$17:S$25,$H4:$H12)*1.03 -> 2463.76 | T32: =SUMPRODUCT(T$17:T$25,$H4:$H12)*1.03 -> 3287.76 | U32: =SUMPRODUCT(U$17:U$25,$H4:$H12)*1.03 -> 3650.32 | V32: =SUMPRODUCT(V$17:V$25,$H4:$H12)*1.03 -> 3650.32 | W32: =SUMPRODUCT(W$17:W$25,$H4:$H12)*1.03 -> 3650.32 | X32: =SUMPRODUCT(X$17:X$25,$H4:$H12)*1.03 -> 3650.32 | ... AB32: =SUMPRODUCT(AB$17:AB$25,$H4:$H12)*1.03 -> 4062.32 | AD32: =SUMPRODUCT(AD$17:AD$25,$H4:$H12)*1.03 -> 5669.12 | AE32: =SUMPRODUCT(AE$17:AE$25,$H4:$H12)*1.03 -> 5669.12 | AF32: =SUMPRODUCT(AF$17:AF$25,$H4:$H12)*1.03 -> 5669.12 | AG32: =SUMPRODUCT(AG$17:AG$25,$H4:$H12)*1.03 -> 6542.56 | AH32: =SUMPRODUCT(AH$17:AH$25,$H4:$H12)*1.03 -> 6542.56 | AI32: =SUMPRODUCT(AI$17:AI$25,$H4:$H12)*1.03 -> 6542.56 | AJ32: =SUMPRODUCT(AJ$17:AJ$25,$H4:$H12)*1.03 -> 6542.56 | AK32: =SUMPRODUCT(AK$17:AK$25,$H4:$H12)*1.03 -> 6542.56 | ... AO32: =SUMPRODUCT(AO$17:AO$25,$H4:$H12)*1.03 -> 7177.04
B33: Soc. Lasten | D33: =SUMPRODUCT(D$17:D$25,$I4:$I12) -> 549.55333 | E33: =SUMPRODUCT(E$17:E$25,$I4:$I12) -> 549.55333 | F33: =SUMPRODUCT(F$17:F$25,$I4:$I12) -> 549.55333 | G33: =SUMPRODUCT(G$17:G$25,$I4:$I12) -> 549.55333 | H33: =SUMPRODUCT(H$17:H$25,$I4:$I12) -> 549.55333 | I33: =SUMPRODUCT(I$17:I$25,$I4:$I12) -> 549.55333 | J33: =SUMPRODUCT(J$17:J$25,$I4:$I12) -> 4333.0167 | K33: =SUMPRODUCT(K$17:K$25,$I4:$I12) -> 4333.0167 | ... O33: =SUMPRODUCT(O$17:O$25,$I4:$I12) -> 4713.4767 | Q33: =SUMPRODUCT(Q$17:Q$25,$I4:$I12)*1.03 -> 6509.4592 | R33: =SUMPRODUCT(R$17:R$25,$I4:$I12)*1.03 -> 6509.4592 | S33: =SUMPRODUCT(S$17:S$25,$I4:$I12)*1.03 -> 6509.4592 | T33: =SUMPRODUCT(T$17:T$25,$I4:$I12)*1.03 -> 8686.5359 | U33: =SUMPRODUCT(U$17:U$25,$I4:$I12)*1.03 -> 9644.4496 | V33: =SUMPRODUCT(V$17:V$25,$I4:$I12)*1.03 -> 9644.4496 | W33: =SUMPRODUCT(W$17:W$25,$I4:$I12)*1.03 -> 9644.4496 | X33: =SUMPRODUCT(X$17:X$25,$I4:$I12)*1.03 -> 9644.4496 | ... AB33: =SUMPRODUCT(AB$17:AB$25,$I4:$I12)*1.03 -> 10732.988 | AD33: =SUMPRODUCT(AD$17:AD$25,$I4:$I12)*1.03 -> 14978.287 | AE33: =SUMPRODUCT(AE$17:AE$25,$I4:$I12)*1.03 -> 14978.287 | AF33: =SUMPRODUCT(AF$17:AF$25,$I4:$I12)*1.03 -> 14978.287 | AG33: =SUMPRODUCT(AG$17:AG$25,$I4:$I12)*1.03 -> 17285.989 | AH33: =SUMPRODUCT(AH$17:AH$25,$I4:$I12)*1.03 -> 17285.989 | AI33: =SUMPRODUCT(AI$17:AI$25,$I4:$I12)*1.03 -> 17285.989 | AJ33: =SUMPRODUCT(AJ$17:AJ$25,$I4:$I12)*1.03 -> 17285.989 | AK33: =SUMPRODUCT(AK$17:AK$25,$I4:$I12)*1.03 -> 17285.989 | ... AO33: =SUMPRODUCT(AO$17:AO$25,$I4:$I12)*1.03 -> 18962.338
B34: Vergoedingen | D34: =SUMPRODUCT(D$17:D$25,$L4:$L12) -> 100 | E34: =SUMPRODUCT(E$17:E$25,$L4:$L12) -> 100 | F34: =SUMPRODUCT(F$17:F$25,$L4:$L12) -> 100 | G34: =SUMPRODUCT(G$17:G$25,$L4:$L12) -> 100 | H34: =SUMPRODUCT(H$17:H$25,$L4:$L12) -> 100 | I34: =SUMPRODUCT(I$17:I$25,$L4:$L12) -> 100 | J34: =SUMPRODUCT(J$17:J$25,$L4:$L12) -> 250 | K34: =SUMPRODUCT(K$17:K$25,$L4:$L12) -> 250 | ... O34: =SUMPRODUCT(O$17:O$25,$L4:$L12) -> 280 | Q34: =SUMPRODUCT(Q$17:Q$25,$L4:$L12) -> 400 | R34: =SUMPRODUCT(R$17:R$25,$L4:$L12) -> 400 | S34: =SUMPRODUCT(S$17:S$25,$L4:$L12) -> 400 | T34: =SUMPRODUCT(T$17:T$25,$L4:$L12) -> 520 | U34: =SUMPRODUCT(U$17:U$25,$L4:$L12) -> 600 | V34: =SUMPRODUCT(V$17:V$25,$L4:$L12) -> 600 | W34: =SUMPRODUCT(W$17:W$25,$L4:$L12) -> 600 | X34: =SUMPRODUCT(X$17:X$25,$L4:$L12) -> 600 | ... AB34: =SUMPRODUCT(AB$17:AB$25,$L4:$L12) -> 670 | AD34: =SUMPRODUCT(AD$17:AD$25,$L4:$L12) -> 960 | AE34: =SUMPRODUCT(AE$17:AE$25,$L4:$L12) -> 960 | AF34: =SUMPRODUCT(AF$17:AF$25,$L4:$L12) -> 960 | AG34: =SUMPRODUCT(AG$17:AG$25,$L4:$L12) -> 1070 | AH34: =SUMPRODUCT(AH$17:AH$25,$L4:$L12) -> 1070 | AI34: =SUMPRODUCT(AI$17:AI$25,$L4:$L12) -> 1070 | AJ34: =SUMPRODUCT(AJ$17:AJ$25,$L4:$L12) -> 1070 | AK34: =SUMPRODUCT(AK$17:AK$25,$L4:$L12) -> 1070 | ... AO34: =SUMPRODUCT(AO$17:AO$25,$L4:$L12) -> 1190
B35: Overige personeelskosten (3%) | D35: =0.03*SUM(D29:D30) -> 84.24 | E35: =0.03*SUM(E29:E30) -> 84.24 | F35: =0.03*SUM(F29:F30) -> 84.24 | G35: =0.03*SUM(G29:G30) -> 84.24 | H35: =0.03*SUM(H29:H30) -> 84.24 | I35: =0.03*SUM(I29:I30) -> 84.24 | J35: =0.03*SUM(J29:J30) -> 664.2 | K35: =0.03*SUM(K29:K30) -> 664.2 | ... O35: =0.03*SUM(O29:O30) -> 722.52 | Q35: =0.03*SUM(Q29:Q30) -> 997.8228 | R35: =0.03*SUM(R29:R30) -> 997.8228 | S35: =0.03*SUM(S29:S30) -> 997.8228 | T35: =0.03*SUM(T29:T30) -> 1331.5428 | U35: =0.03*SUM(U29:U30) -> 1478.3796 | V35: =0.03*SUM(V29:V30) -> 1478.3796 | W35: =0.03*SUM(W29:W30) -> 1478.3796 | X35: =0.03*SUM(X29:X30) -> 1478.3796 | ... AB35: =0.03*SUM(AB29:AB30) -> 1645.2396 | AD35: =0.03*SUM(AD29:AD30) -> 2295.9936 | AE35: =0.03*SUM(AE29:AE30) -> 2295.9936 | AF35: =0.03*SUM(AF29:AF30) -> 2295.9936 | AG35: =0.03*SUM(AG29:AG30) -> 2649.7368 | AH35: =0.03*SUM(AH29:AH30) -> 2649.7368 | AI35: =0.03*SUM(AI29:AI30) -> 2649.7368 | AJ35: =0.03*SUM(AJ29:AJ30) -> 2649.7368 | AK35: =0.03*SUM(AK29:AK30) -> 2649.7368 | ... AO35: =0.03*SUM(AO29:AO30) -> 2906.7012
B36: Autokosten | D36: =SUMPRODUCT(D$17:D$25,$J4:$J12) -> 1080 | E36: =SUMPRODUCT(E$17:E$25,$J4:$J12) -> 1080 | F36: =SUMPRODUCT(F$17:F$25,$J4:$J12) -> 1080 | G36: =SUMPRODUCT(G$17:G$25,$J4:$J12) -> 1080 | H36: =SUMPRODUCT(H$17:H$25,$J4:$J12) -> 1080 | I36: =SUMPRODUCT(I$17:I$25,$J4:$J12) -> 1080 | J36: =SUMPRODUCT(J$17:J$25,$J4:$J12) -> 2960 | K36: =SUMPRODUCT(K$17:K$25,$J4:$J12) -> 2960 | ... O36: =SUMPRODUCT(O$17:O$25,$J4:$J12) -> 3080 | Q36: =SUMPRODUCT(Q$17:Q$25,$J4:$J12) -> 4440 | R36: =SUMPRODUCT(R$17:R$25,$J4:$J12) -> 4440 | S36: =SUMPRODUCT(S$17:S$25,$J4:$J12) -> 4440 | T36: =SUMPRODUCT(T$17:T$25,$J4:$J12) -> 5950 | U36: =SUMPRODUCT(U$17:U$25,$J4:$J12) -> 6770 | V36: =SUMPRODUCT(V$17:V$25,$J4:$J12) -> 6770 | W36: =SUMPRODUCT(W$17:W$25,$J4:$J12) -> 6770 | X36: =SUMPRODUCT(X$17:X$25,$J4:$J12) -> 6770 | ... AB36: =SUMPRODUCT(AB$17:AB$25,$J4:$J12) -> 7430 | AD36: =SUMPRODUCT(AD$17:AD$25,$J4:$J12) -> 10780 | AE36: =SUMPRODUCT(AE$17:AE$25,$J4:$J12) -> 10780 | AF36: =SUMPRODUCT(AF$17:AF$25,$J4:$J12) -> 10780 | AG36: =SUMPRODUCT(AG$17:AG$25,$J4:$J12) -> 12190 | AH36: =SUMPRODUCT(AH$17:AH$25,$J4:$J12) -> 12190 | AI36: =SUMPRODUCT(AI$17:AI$25,$J4:$J12) -> 12190 | AJ36: =SUMPRODUCT(AJ$17:AJ$25,$J4:$J12) -> 12190 | AK36: =SUMPRODUCT(AK$17:AK$25,$J4:$J12) -> 12190 | ... AO36: =SUMPRODUCT(AO$17:AO$25,$J4:$J12) -> 13650
B37: Brandstof | D37: =SUMPRODUCT(D$17:D$25,$K4:$K12) -> 220 | E37: =SUMPRODUCT(E$17:E$25,$K4:$K12) -> 220 | F37: =SUMPRODUCT(F$17:F$25,$K4:$K12) -> 220 | G37: =SUMPRODUCT(G$17:G$25,$K4:$K12) -> 220 | H37: =SUMPRODUCT(H$17:H$25,$K4:$K12) -> 220 | I37: =SUMPRODUCT(I$17:I$25,$K4:$K12) -> 220 | J37: =SUMPRODUCT(J$17:J$25,$K4:$K12) -> 550 | K37: =SUMPRODUCT(K$17:K$25,$K4:$K12) -> 550 | ... O37: =SUMPRODUCT(O$17:O$25,$K4:$K12) -> 550 | Q37: =SUMPRODUCT(Q$17:Q$25,$K4:$K12) -> 770 | R37: =SUMPRODUCT(R$17:R$25,$K4:$K12) -> 770 | S37: =SUMPRODUCT(S$17:S$25,$K4:$K12) -> 770 | T37: =SUMPRODUCT(T$17:T$25,$K4:$K12) -> 1040 | U37: =SUMPRODUCT(U$17:U$25,$K4:$K12) -> 1180 | V37: =SUMPRODUCT(V$17:V$25,$K4:$K12) -> 1180 | W37: =SUMPRODUCT(W$17:W$25,$K4:$K12) -> 1180 | X37: =SUMPRODUCT(X$17:X$25,$K4:$K12) -> 1180 | ... AB37: =SUMPRODUCT(AB$17:AB$25,$K4:$K12) -> 1280 | AD37: =SUMPRODUCT(AD$17:AD$25,$K4:$K12) -> 1880 | AE37: =SUMPRODUCT(AE$17:AE$25,$K4:$K12) -> 1880 | AF37: =SUMPRODUCT(AF$17:AF$25,$K4:$K12) -> 1880 | AG37: =SUMPRODUCT(AG$17:AG$25,$K4:$K12) -> 2130 | AH37: =SUMPRODUCT(AH$17:AH$25,$K4:$K12) -> 2130 | AI37: =SUMPRODUCT(AI$17:AI$25,$K4:$K12) -> 2130 | AJ37: =SUMPRODUCT(AJ$17:AJ$25,$K4:$K12) -> 2130 | AK37: =SUMPRODUCT(AK$17:AK$25,$K4:$K12) -> 2130 | ... AO37: =SUMPRODUCT(AO$17:AO$25,$K4:$K12) -> 2400
B38: Managementfee | D38: =SUMPRODUCT(D$17:D$25,$D4:$D12) -> 8000 | E38: =SUMPRODUCT(E$17:E$25,$D4:$D12) -> 8000 | F38: =SUMPRODUCT(F$17:F$25,$D4:$D12) -> 8000 | G38: =SUMPRODUCT(G$17:G$25,$D4:$D12) -> 8000 | H38: =SUMPRODUCT(H$17:H$25,$D4:$D12) -> 8000 | I38: =SUMPRODUCT(I$17:I$25,$D4:$D12) -> 8000 | J38: =SUMPRODUCT(J$17:J$25,$D4:$D12) -> 8000 | K38: =SUMPRODUCT(K$17:K$25,$D4:$D12) -> 8000 | ... O38: =SUMPRODUCT(O$17:O$25,$D4:$D12) -> 8000 | Q38: =SUMPRODUCT(Q$17:Q$25,$D4:$D12) -> 13000 | R38: =SUMPRODUCT(R$17:R$25,$D4:$D12) -> 13000 | S38: =SUMPRODUCT(S$17:S$25,$D4:$D12) -> 13000 | T38: =SUMPRODUCT(T$17:T$25,$D4:$D12) -> 16000 | U38: =SUMPRODUCT(U$17:U$25,$D4:$D12) -> 20000 | V38: =SUMPRODUCT(V$17:V$25,$D4:$D12) -> 20000 | W38: =SUMPRODUCT(W$17:W$25,$D4:$D12) -> 20000 | X38: =SUMPRODUCT(X$17:X$25,$D4:$D12) -> 20000 | ... AB38: =SUMPRODUCT(AB$17:AB$25,$D4:$D12) -> 22000 | AD38: =SUMPRODUCT(AD$17:AD$25,$D4:$D12) -> 34000 | AE38: =SUMPRODUCT(AE$17:AE$25,$D4:$D12) -> 34000 | AF38: =SUMPRODUCT(AF$17:AF$25,$D4:$D12) -> 34000 | AG38: =SUMPRODUCT(AG$17:AG$25,$D4:$D12) -> 36000 | AH38: =SUMPRODUCT(AH$17:AH$25,$D4:$D12) -> 36000 | AI38: =SUMPRODUCT(AI$17:AI$25,$D4:$D12) -> 36000 | AJ38: =SUMPRODUCT(AJ$17:AJ$25,$D4:$D12) -> 36000 | AK38: =SUMPRODUCT(AK$17:AK$25,$D4:$D12) -> 36000 | ... AO38: =SUMPRODUCT(AO$17:AO$25,$D4:$D12) -> 42000
B41: Huisvesting | D41: =SUM(D42:D43) -> 2200 | E41: =SUM(E42:E43) -> 2200 | F41: =SUM(F42:F43) -> 2200 | G41: =SUM(G42:G43) -> 2200 | H41: =SUM(H42:H43) -> 2200 | I41: =SUM(I42:I43) -> 2200 | J41: =SUM(J42:J43) -> 3850 | K41: =SUM(K42:K43) -> 3850 | ... O41: =SUM(O42:O43) -> 3850 | Q41: =SUM(Q42:Q43) -> 3965.5 | R41: =SUM(R42:R43) -> 3965.5 | S41: =SUM(S42:S43) -> 3965.5 | T41: =SUM(T42:T43) -> 3965.5 | U41: =SUM(U42:U43) -> 3965.5 | V41: =SUM(V42:V43) -> 7700 | W41: =SUM(W42:W43) -> 7700 | X41: =SUM(X42:X43) -> 7700 | ... AB41: =SUM(AB42:AB43) -> 7700 | AD41: =SUM(AD42:AD43) -> 11231 | AE41: =SUM(AE42:AE43) -> 11231 | AF41: =SUM(AF42:AF43) -> 11231 | AG41: =SUM(AG42:AG43) -> 11231 | AH41: =SUM(AH42:AH43) -> 11231 | AI41: =SUM(AI42:AI43) -> 11231 | AJ41: =SUM(AJ42:AJ43) -> 11231 | AK41: =SUM(AK42:AK43) -> 11231 | ... AO41: =SUM(AO42:AO43) -> 11231
B42: - Huur | D42: 2000 | E42: 2000 | F42: 2000 | G42: 2000 | H42: 2000 | I42: 2000 | J42: =I42+1500 -> 3500 | K42: =J42 -> 3500 | L42: =K42 -> 3500 | M42: =L42 -> 3500 | N42: =M42 -> 3500 | O42: =N42 -> 3500 | Q42: =O42*1.03 -> 3605 | R42: =Q42 -> 3605 | S42: =R42 -> 3605 | T42: =S42 -> 3605 | U42: =T42 -> 3605 | V42: =7000 -> 7000 | W42: =V42 -> 7000 | X42: =W42 -> 7000 | Y42: =X42 -> 7000 | Z42: =Y42 -> 7000 | AA42: =Z42 -> 7000 | AB42: =AA42 -> 7000 | AD42: =AB42*1.03+3000 -> 10210 | AE42: =AD42 -> 10210 | AF42: =AE42 -> 10210 | AG42: =AF42 -> 10210 | AH42: =AG42 -> 10210 | AI42: =AH42 -> 10210 | AJ42: =AI42 -> 10210 | AK42: =AJ42 -> 10210 | AL42: =AK42 -> 10210 | ... AO42: =AN42 -> 10210
